Workbook

Sheet Sheet1 (2)
A1: Date | B1: Country | C1: CER
A2: 45292 | B2: Argentina | C2: 185.6531
A3: 45293 | B3: Argentina | C3: 186.3758
A4: 45294 | B4: Argentina | C4: 187.1013
A5: 45295 | B5: Argentina | C5: 187.8297
A6: 45296 | B6: Argentina | C6: 188.5609
A7: 45297 | B7: Argentina | C7: 189.295
A8: 45298 | B8: Argentina | C8: 190.0319
A9: 45299 | B9: Argentina | C9: 190.7717
A10: 45300 | B10: Argentina | C10: 191.5143
A11: 45301 | B11: Argentina | C11: 192.2599
A12: 45302 | B12: Argentina | C12: 193.0083
A13: 45303 | B13: Argentina | C13: 193.7597
... A837: 46127 | B837: Argentina | C837: 745.54955

Sheet Sheet1
A1: Date | B1: price - TZX26 | C1: price - TZXD5 | D1: price - TZXD6 | E1: price - TZXM6 | F1: price - TZXM7 | G1: price - T15D5 | H1: price - TZXO6 | I1: price - T30J6 | J1: price - TTD26 | K1: price - TTM26 | L1: price - S29Y6 | M1: price - T30A7 | N1: price - S30O6 | O1: price - X29Y6 | P1: price - S17A6 | Q1: irr - TZX26 | R1: irr - TZXD5 | S1: irr - TZXD6 | T1: irr - TZXM6 | U1: irr - TZXM7 | V1: irr - T15D5 | W1: irr - TZXO6 | X1: irr - T30J6 | Y1: irr - TTD26 | Z1: irr - TTM26 | AA1: irr - S29Y6 | AB1: irr - T30A7 | AC1: irr - S30O6 | AD1: irr - X29Y6 | AE1: irr - S17A6
A2: 45323 | B2: 111.4 | Q2: -0.043203243
A3: 45324 | B3: 111.75 | Q3: -0.041608168
A4: 45327 | B4: 116.25 | Q4: -0.04861356
A5: 45328 | B5: 119.9 | Q5: -0.057855736
A6: 45329 | B6: 121.75 | Q6: -0.061013262
A7: 45330 | B7: 122 | Q7: -0.059036011
A8: 45331 | B8: 121.4 | Q8: -0.054328419
A9: 45334 | B9: 121.4 | Q9: -0.045861936
A10: 45335 | B10: 121.4 | Q10: -0.043009681
A11: 45336 | B11: 120.5 | Q11: -0.037172164
A12: 45337 | B12: 121 | Q12: -0.035938223
A13: 45338 | B13: 121.9 | Q13: -0.036012657
... A32: 45365 | B32: 156.8 | Q32: -0.065500506
A33: 45366 | B33: 165.7 | C33: 121.35 | D33: 115.5 | Q33: -0.084964489 | R33: -0.10313387 | S33: -0.050308452
A34: 45369 | B34: 173.15 | C34: 129 | D34: 123 | Q34: -0.094919623 | R34: -0.12449984 | S34: -0.065192409
A35: 45370 | B35: 172.05 | C35: 131.4 | D35: 125.7 | Q35: -0.089995461 | R35: -0.13059596 | S35: -0.070369655
A36: 45371 | B36: 171 | C36: 131.9 | D36: 126 | Q36: -0.085132034 | R36: -0.12947525 | S36: -0.069072749
A37: 45372 | B37: 173.75 | C37: 132.5 | D37: 129.9 | Q37: -0.088984984 | R37: -0.12871601 | S37: -0.077163386
A38: 45373 | B38: 181 | C38: 134 | D38: 130.9 | Q38: -0.1025857 | R38: -0.13127954 | S38: -0.077640283
A39: 45376 | B39: 185.5 | Q39: -0.10495883
A40: 45377 | B40: 175.75 | C40: 130.5 | D40: 123.75 | Q40: -0.082171699 | R40: -0.10694032 | S40: -0.050989628
A41: 45378 | B41: 172.45 | C41: 131.25 | D41: 120 | Q41: -0.073028324 | R41: -0.10798679 | S41: -0.039001457
A42: 45379 | B42: 172.45 | C42: 131.25 | D42: 120 | Q42: -0.071492579 | R42: -0.10609894 | S42: -0.037644185
A43: 45380 | B43: 172.45 | C43: 131.25 | D43: 120 | Q43: -0.069950554 | R43: -0.10420105 | S43: -0.036282256
A44: 45383 | B44: 172.45 | C44: 131.25 | D44: 120 | Q44: -0.065286416 | R44: -0.098446363 | S44: -0.032168284
A45: 45384 | B45: 172.45 | C45: 131.25 | D45: 120 | Q45: -0.063718889 | R45: -0.096507532 | S45: -0.030787487
A46: 45385 | B46: 171.25 | C46: 140 | D46: 126.5 | Q46: -0.059258297 | R46: -0.12780826 | S46: -0.047916611
A47: 45386 | B47: 173.1 | C47: 130.8 | D47: 124 | Q47: -0.062120453 | R47: -0.090787175 | S47: -0.039590447
A48: 45387 | B48: 179.5 | Q48: -0.075465605
A49: 45390 | B49: 184.85 | C49: 136.5 | D49: 129.4 | Q49: -0.082815354 | R49: -0.10539484 | S49: -0.049086449
A50: 45391 | B50: 188.25 | C50: 137.2 | D50: 133 | Q50: -0.088679223 | R50: -0.10614075 | S50: -0.057288098
A51: 45392 | B51: 192.9 | Q51: -0.096998501
A52: 45393 | B52: 198.25 | C52: 145.1 | Q52: -0.10643659 | R52: -0.13129618
A53: 45394 | B53: 199.6 | C53: 148 | D53: 143 | Q53: -0.10766821 | R53: -0.13952524 | S53: -0.0782371
A54: 45397 | B54: 205.8 | Q54: -0.11542233
A55: 45398 | B55: 200.5 | C55: 150 | Q55: -0.1035751 | R55: -0.13906377
A56: 45399 | B56: 195.75 | C56: 148 | Q56: -0.092399006 | R56: -0.13033617
A57: 45400 | B57: 188.8 | C57: 149.7 | Q57: -0.076025997 | R57: -0.13436142
A58: 45401 | B58: 187.7 | C58: 148.75 | D58: 132.1 | Q58: -0.072026163 | R58: -0.12921334 | S58: -0.041359465
...

Sheet <<NO TOCAR

Sheet Inflación BE
D1: S17A6 - TZXM6 | H1: T30J6 - TZX26 | L1: S30O6 - TZXO6 | P1: S29Y6 - X29Y6 | T1: T30A7 - TZXM7 | X1: S15Y6 - X15Y6 | AB1: S31L6 - X31L6 | AF1: S30S6 - X30S6 | AJ1: S30N6 - X30N6
A2: Fecha | B2: Último CER | C2: CER hoy | D2: Fecha vencimiento | E2: Fecha de vencimiento CER | F2: CER implícito | G2: Inflación implícita | H2: Fecha vencimiento | I2: Fecha de vencimiento CER | J2: CER implícito | K2: Inflación implícita | L2: Fecha vencimiento | M2: Fecha de vencimiento CER | N2: CER implícito | O2: Inflación implícita | P2: Fecha vencimiento | Q2: Fecha de vencimiento CER | R2: CER implícito | S2: Inflación implícita | T2: Fecha vencimiento | U2: Fecha de vencimiento CER | V2: CER implícito | W2: Inflación implícita | X2: Fecha vencimiento | Y2: Fecha de vencimiento CER | Z2: CER implícito | AA2: Inflación implícita | AB2: Fecha vencimiento | AC2: Fecha de vencimiento CER | AD2: CER implícito | AE2: Inflación implícita | AF2: Fecha vencimiento | AG2: Fecha de vencimiento CER | AH2: CER implícito | AI2: Inflación implícita | AJ2: Fecha vencimiento | AK2: Fecha de vencimiento CER | AL2: CER implícito | AM2: Inflación implícita
A3: =+[1]CER_implicito!$A420 -> 45974 | B3: 45976 | C3: =+VLOOKUP(B3,'Sheet1 (2)'!A:C,3) -> 653.21049 | H3: 46202 | I3: =+WORKDAY.INTL(H3,-10,1,Feriados!$A$2:$A$1048576) -> 46184 | J3: =+VLOOKUP(A3,[1]CER_implicito!$A:$G,4) -> 742.24797 | K3: =+(J3/C3)^(30/(I3-B3))-1 -> 0.018601266 | L3: 46324 | M3: =+WORKDAY.INTL(L3,-10,1,Feriados!$A$2:$A$1048576) -> 46310 | N3: =+VLOOKUP(A3,[1]CER_implicito!$A:$G,6) -> 794.77175 | O3: =+(N3/C3)^(30/(M3-B3))-1 -> 0.017774887 | T3: 46507 | U3: =+WORKDAY.INTL(T3,-10,1,Feriados!$A$2:$A$1048576) -> 46493 | V3: =+VLOOKUP(A3,[1]CER_implicito!$A:$G,5) -> 861.91777 | W3: =+(V3/C3)^(30/(U3-B3))-1 -> 0.016218733
A4: =+[1]CER_implicito!$A421 -> 45975 | B4: 46006 | C4: =+VLOOKUP(B4,'Sheet1 (2)'!A:C,3) -> 668.23433 | H4: 46202 | I4: =+WORKDAY.INTL(H4,-10,1,Feriados!$A$2:$A$1048576) -> 46184 | J4: =+VLOOKUP(A4,[1]CER_implicito!$A:$G,4) -> 739.63156 | K4: =+(J4/C4)^(30/(I4-B4))-1 -> 0.017256173 | L4: 46324 | M4: =+WORKDAY.INTL(L4,-10,1,Feriados!$A$2:$A$1048576) -> 46310 | N4: =+VLOOKUP(A4,[1]CER_implicito!$A:$G,6) -> 792.86688 | O4: =+(N4/C4)^(30/(M4-B4))-1 -> 0.017019836 | T4: =+T3 -> 46507 | U4: =+U3 -> 46493 | V4: =+VLOOKUP(A4,[1]CER_implicito!$A:$G,5) -> 859.83044 | W4: =+(V4/C4)^(30/(U4-B4))-1 -> 0.015650756
A5: =+[1]CER_implicito!$A422 -> 45978 | B5: 46006 | C5: =+VLOOKUP(B5,'Sheet1 (2)'!A:C,3) -> 668.23433 | H5: 46202 | I5: =+WORKDAY.INTL(H5,-10,1,Feriados!$A$2:$A$1048576) -> 46184 | J5: =+VLOOKUP(A5,[1]CER_implicito!$A:$G,4) -> 739.83268 | K5: =+(J5/C5)^(30/(I5-B5))-1 -> 0.017302789 | L5: 46324 | M5: =+WORKDAY.INTL(L5,-10,1,Feriados!$A$2:$A$1048576) -> 46310 | N5: =+VLOOKUP(A5,[1]CER_implicito!$A:$G,6) -> 791.47917 | O5: =+(N5/C5)^(30/(M5-B5))-1 -> 0.016844037 | T5: =+T4 -> 46507 | U5: =+U4 -> 46493 | V5: =+VLOOKUP(A5,[1]CER_implicito!$A:$G,5) -> 862.45834 | W5: =+(V5/C5)^(30/(U5-B5))-1 -> 0.015841703
A6: =+[1]CER_implicito!$A423 -> 45979 | B6: 46006 | C6: =+VLOOKUP(B6,'Sheet1 (2)'!A:C,3) -> 668.23433 | H6: 46202 | I6: =+WORKDAY.INTL(H6,-10,1,Feriados!$A$2:$A$1048576) -> 46184 | J6: =+VLOOKUP(A6,[1]CER_implicito!$A:$G,4) -> 741.93269 | K6: =+(J6/C6)^(30/(I6-B6))-1 -> 0.017788891 | L6: 46324 | M6: =+WORKDAY.INTL(L6,-10,1,Feriados!$A$2:$A$1048576) -> 46310 | N6: =+VLOOKUP(A6,[1]CER_implicito!$A:$G,6) -> 794.6249 | O6: =+(N6/C6)^(30/(M6-B6))-1 -> 0.01724215 | T6: =+T5 -> 46507 | U6: =+U5 -> 46493 | V6: =+VLOOKUP(A6,[1]CER_implicito!$A:$G,5) -> 856.13145 | W6: =+(V6/C6)^(30/(U6-B6))-1 -> 0.015381054
A7: =+[1]CER_implicito!$A424 -> 45980 | B7: 46006 | C7: =+VLOOKUP(B7,'Sheet1 (2)'!A:C,3) -> 668.23433 | H7: 46202 | I7: =+WORKDAY.INTL(H7,-10,1,Feriados!$A$2:$A$1048576) -> 46184 | J7: =+VLOOKUP(A7,[1]CER_implicito!$A:$G,4) -> 742.37598 | K7: =+(J7/C7)^(30/(I7-B7))-1 -> 0.017891355 | L7: 46324 | M7: =+WORKDAY.INTL(L7,-10,1,Feriados!$A$2:$A$1048576) -> 46310 | N7: =+VLOOKUP(A7,[1]CER_implicito!$A:$G,6) -> 793.92094 | O7: =+(N7/C7)^(30/(M7-B7))-1 -> 0.017153183 | T7: =+T6 -> 46507 | U7: =+U6 -> 46493 | V7: =+VLOOKUP(A7,[1]CER_implicito!$A:$G,5) -> 865.9161 | W7: =+(V7/C7)^(30/(U7-B7))-1 -> 0.016092117
A8: =+[1]CER_implicito!$A425 -> 45981 | B8: 46006 | C8: =+VLOOKUP(B8,'Sheet1 (2)'!A:C,3) -> 668.23433 | H8: 46202 | I8: =+WORKDAY.INTL(H8,-10,1,Feriados!$A$2:$A$1048576) -> 46184 | J8: =+VLOOKUP(A8,[1]CER_implicito!$A:$G,4) -> 747.89722 | K8: =+(J8/C8)^(30/(I8-B8))-1 -> 0.019163325 | L8: 46324 | M8: =+WORKDAY.INTL(L8,-10,1,Feriados!$A$2:$A$1048576) -> 46310 | N8: =+VLOOKUP(A8,[1]CER_implicito!$A:$G,6) -> 797.36194 | O8: =+(N8/C8)^(30/(M8-B8))-1 -> 0.017587388 | T8: =+T7 -> 46507 | U8: =+U7 -> 46493 | V8: =+VLOOKUP(A8,[1]CER_implicito!$A:$G,5) -> 867.98852 | W8: =+(V8/C8)^(30/(U8-B8))-1 -> 0.016241755
A9: =+[1]CER_implicito!$A426 -> 45982 | B9: 46006 | C9: =+VLOOKUP(B9,'Sheet1 (2)'!A:C,3) -> 668.23433 | H9: 46202 | I9: =+WORKDAY.INTL(H9,-10,1,Feriados!$A$2:$A$1048576) -> 46184 | J9: =+VLOOKUP(A9,[1]CER_implicito!$A:$G,4) -> 0 | K9: =+(J9/C9)^(30/(I9-B9))-1 -> -1 | L9: 46324 | M9: =+WORKDAY.INTL(L9,-10,1,Feriados!$A$2:$A$1048576) -> 46310 | N9: =+VLOOKUP(A9,[1]CER_implicito!$A:$G,6) -> 0 | O9: =+(N9/C9)^(30/(M9-B9))-1 -> -1 | T9: =+T8 -> 46507 | U9: =+U8 -> 46493 | V9: =+VLOOKUP(A9,[1]CER_implicito!$A:$G,5) -> 0 | W9: =+(V9/C9)^(30/(U9-B9))-1 -> -1
A10: =+[1]CER_implicito!$A427 -> 45986 | B10: 46006 | C10: =+VLOOKUP(B10,'Sheet1 (2)'!A:C,3) -> 668.23433 | H10: 46202 | I10: =+WORKDAY.INTL(H10,-10,1,Feriados!$A$2:$A$1048576) -> 46184 | J10: =+VLOOKUP(A10,[1]CER_implicito!$A:$G,4) -> 746.36266 | K10: =+(J10/C10)^(30/(I10-B10))-1 -> 0.018810582 | L10: 46324 | M10: =+WORKDAY.INTL(L10,-10,1,Feriados!$A$2:$A$1048576) -> 46310 | N10: =+VLOOKUP(A10,[1]CER_implicito!$A:$G,6) -> 793.73991 | O10: =+(N10/C10)^(30/(M10-B10))-1 -> 0.017130293 | T10: =+T9 -> 46507 | U10: =+U9 -> 46493 | V10: =+VLOOKUP(A10,[1]CER_implicito!$A:$G,5) -> 868.10671 | W10: =+(V10/C10)^(30/(U10-B10))-1 -> 0.016250278
A11: =+[1]CER_implicito!$A428 -> 45987 | B11: 46006 | C11: =+VLOOKUP(B11,'Sheet1 (2)'!A:C,3) -> 668.23433 | H11: 46202 | I11: =+WORKDAY.INTL(H11,-10,1,Feriados!$A$2:$A$1048576) -> 46184 | J11: =+VLOOKUP(A11,[1]CER_implicito!$A:$G,4) -> 747.72902 | K11: =+(J11/C11)^(30/(I11-B11))-1 -> 0.019124691 | L11: 46324 | M11: =+WORKDAY.INTL(L11,-10,1,Feriados!$A$2:$A$1048576) -> 46310 | N11: =+VLOOKUP(A11,[1]CER_implicito!$A:$G,6) -> 795.84696 | O11: =+(N11/C11)^(30/(M11-B11))-1 -> 0.017396428 | T11: =+T10 -> 46507 | U11: =+U10 -> 46493 | V11: =+VLOOKUP(A11,[1]CER_implicito!$A:$G,5) -> 869.00189 | W11: =+(V11/C11)^(30/(U11-B11))-1 -> 0.016314802
A12: =+[1]CER_implicito!$A429 -> 45988 | B12: 46006 | C12: =+VLOOKUP(B12,'Sheet1 (2)'!A:C,3) -> 668.23433 | H12: 46202 | I12: =+WORKDAY.INTL(H12,-10,1,Feriados!$A$2:$A$1048576) -> 46184 | J12: =+VLOOKUP(A12,[1]CER_implicito!$A:$G,4) -> 747.91627 | K12: =+(J12/C12)^(30/(I12-B12))-1 -> 0.0191677 | L12: 46324 | M12: =+WORKDAY.INTL(L12,-10,1,Feriados!$A$2:$A$1048576) -> 46310 | N12: =+VLOOKUP(A12,[1]CER_implicito!$A:$G,6) -> 794.73773 | O12: =+(N12/C12)^(30/(M12-B12))-1 -> 0.017256403 | T12: =+T11 -> 46507 | U12: =+U11 -> 46493 | V12: =+VLOOKUP(A12,[1]CER_implicito!$A:$G,5) -> 867.91189 | W12: =+(V12/C12)^(30/(U12-B12))-1 -> 0.016236227
A13: =+[1]CER_implicito!$A430 -> 45989 | B13: 46006 | C13: =+VLOOKUP(B13,'Sheet1 (2)'!A:C,3) -> 668.23433 | H13: 46202 | I13: =+WORKDAY.INTL(H13,-10,1,Feriados!$A$2:$A$1048576) -> 46184 | J13: =+VLOOKUP(A13,[1]CER_implicito!$A:$G,4) -> 747.615 | K13: =+(J13/C13)^(30/(I13-B13))-1 -> 0.019098497 | L13: 46324 | M13: =+WORKDAY.INTL(L13,-10,1,Feriados!$A$2:$A$1048576) -> 46310 | N13: =+VLOOKUP(A13,[1]CER_implicito!$A:$G,6) -> 790.63388 | O13: =+(N13/C13)^(30/(M13-B13))-1 -> 0.016736817 | T13: =+T12 -> 46507 | U13: =+U12 -> 46493 | V13: =+VLOOKUP(A13,[1]CER_implicito!$A:$G,5) -> 864.29714 | W13: =+(V13/C13)^(30/(U13-B13))-1 -> 0.015974987
A14: =+[1]CER_implicito!$A431 -> 45992 | B14: 46006 | C14: =+VLOOKUP(B14,'Sheet1 (2)'!A:C,3) -> 668.23433 | H14: 46202 | I14: =+WORKDAY.INTL(H14,-10,1,Feriados!$A$2:$A$1048576) -> 46184 | J14: =+VLOOKUP(A14,[1]CER_implicito!$A:$G,4) -> 743.88008 | K14: =+(J14/C14)^(30/(I14-B14))-1 -> 0.018238643 | L14: 46324 | M14: =+WORKDAY.INTL(L14,-10,1,Feriados!$A$2:$A$1048576) -> 46310 | N14: =+VLOOKUP(A14,[1]CER_implicito!$A:$G,6) -> 790.85123 | O14: =+(N14/C14)^(30/(M14-B14))-1 -> 0.016764395 | T14: =+T13 -> 46507 | U14: =+U13 -> 46493 | V14: =+VLOOKUP(A14,[1]CER_implicito!$A:$G,5) -> 862.73534 | W14: =+(V14/C14)^(30/(U14-B14))-1 -> 0.015861798
A15: =+[1]CER_implicito!$A432 -> 45993 | B15: 46006 | C15: =+VLOOKUP(B15,'Sheet1 (2)'!A:C,3) -> 668.23433 | H15: 46202 | I15: =+WORKDAY.INTL(H15,-10,1,Feriados!$A$2:$A$1048576) -> 46184 | J15: =+VLOOKUP(A15,[1]CER_implicito!$A:$G,4) -> 742.60707 | K15: =+(J15/C15)^(30/(I15-B15))-1 -> 0.017944751 | L15: 46324 | M15: =+WORKDAY.INTL(L15,-10,1,Feriados!$A$2:$A$1048576) -> 46310 | N15: =+VLOOKUP(A15,[1]CER_implicito!$A:$G,6) -> 790.72969 | O15: =+(N15/C15)^(30/(M15-B15))-1 -> 0.016748975 | T15: =+T14 -> 46507 | U15: =+U14 -> 46493 | V15: =+VLOOKUP(A15,[1]CER_implicito!$A:$G,5) -> 860.14172 | W15: =+(V15/C15)^(30/(U15-B15))-1 -> 0.015673403
... A20: =+[1]CER_implicito!$A437 -> 46001 | B20: 46006 | C20: =+VLOOKUP(B20,'Sheet1 (2)'!A:C,3) -> 668.23433 | H20: 46202 | I20: =+WORKDAY.INTL(H20,-10,1,Feriados!$A$2:$A$1048576) -> 46184 | J20: =+VLOOKUP(A20,[1]CER_implicito!$A:$G,4) -> 742.5736 | K20: =+(J20/C20)^(30/(I20-B20))-1 -> 0.017937018 | L20: 46324 | M20: =+WORKDAY.INTL(L20,-10,1,Feriados!$A$2:$A$1048576) -> 46310 | N20: =+VLOOKUP(A20,[1]CER_implicito!$A:$G,6) -> 785.84933 | O20: =+(N20/C20)^(30/(M20-B20))-1 -> 0.016127968 | T20: =+T19 -> 46507 | U20: =+U19 -> 46493 | V20: =+VLOOKUP(A20,[1]CER_implicito!$A:$G,5) -> 860.58682 | W20: =+(V20/C20)^(30/(U20-B20))-1 -> 0.015705772
A21: =+[1]CER_implicito!$A438 -> 46002 | B21: 46006 | C21: =+VLOOKUP(B21,'Sheet1 (2)'!A:C,3) -> 668.23433 | H21: 46202 | I21: =+WORKDAY.INTL(H21,-10,1,Feriados!$A$2:$A$1048576) -> 46184 | J21: =+VLOOKUP(A21,[1]CER_implicito!$A:$G,4) -> 745.7221 | K21: =+(J21/C21)^(30/(I21-B21))-1 -> 0.018663161 | L21: 46324 | M21: =+WORKDAY.INTL(L21,-10,1,Feriados!$A$2:$A$1048576) -> 46310 | N21: =+VLOOKUP(A21,[1]CER_implicito!$A:$G,6) -> 786.86073 | O21: =+(N21/C21)^(30/(M21-B21))-1 -> 0.016256949 | P21: 46171 | Q21: =+WORKDAY.INTL(P21,-10,1,Feriados!$A$2:$A$1048576) -> 46156 | R21: =+VLOOKUP(A21,[1]CER_implicito!$A:$G,7) -> 734.20924 | S21: =+(R21/C21)^(30/(Q21-B21))-1 -> 0.019009453 | T21: =+T20 -> 46507 | U21: =+U20 -> 46493 | V21: =+VLOOKUP(A21,[1]CER_implicito!$A:$G,5) -> 862.52293 | W21: =+(V21/C21)^(30/(U21-B21))-1 -> 0.015846389
A22: =+[1]CER_implicito!$A439 -> 46003 | B22: 46006 | C22: =+VLOOKUP(B22,'Sheet1 (2)'!A:C,3) -> 668.23433 | H22: 46202 | I22: =+WORKDAY.INTL(H22,-10,1,Feriados!$A$2:$A$1048576) -> 46184 | J22: =+VLOOKUP(A22,[1]CER_implicito!$A:$G,4) -> 748.74002 | K22: =+(J22/C22)^(30/(I22-B22))-1 -> 0.0193568 | L22: 46324 | M22: =+WORKDAY.INTL(L22,-10,1,Feriados!$A$2:$A$1048576) -> 46310 | N22: =+VLOOKUP(A22,[1]CER_implicito!$A:$G,6) -> 787.72296 | O22: =+(N22/C22)^(30/(M22-B22))-1 -> 0.01636679 | P22: 46171 | Q22: =+WORKDAY.INTL(P22,-10,1,Feriados!$A$2:$A$1048576) -> 46156 | R22: =+VLOOKUP(A22,[1]CER_implicito!$A:$G,7) -> 736.06313 | S22: =+(R22/C22)^(30/(Q22-B22))-1 -> 0.019523537 | T22: =+T21 -> 46507 | U22: =+U21 -> 46493 | V22: =+VLOOKUP(A22,[1]CER_implicito!$A:$G,5) -> 862.37513 | W22: =+(V22/C22)^(30/(U22-B22))-1 -> 0.015835665
A23: =+[1]CER_implicito!$A440 -> 46006 | B23: 46037 | C23: =+VLOOKUP(B23,'Sheet1 (2)'!A:C,3) -> 684.94019 | H23: 46202 | I23: =+WORKDAY.INTL(H23,-10,1,Feriados!$A$2:$A$1048576) -> 46184 | J23: =+VLOOKUP(A23,[1]CER_implicito!$A:$G,4) -> 755.54177 | K23: =+(J23/C23)^(30/(I23-B23))-1 -> 0.020222901 | L23: 46324 | M23: =+WORKDAY.INTL(L23,-10,1,Feriados!$A$2:$A$1048576) -> 46310 | N23: =+VLOOKUP(A23,[1]CER_implicito!$A:$G,6) -> 791.52794 | O23: =+(N23/C23)^(30/(M23-B23))-1 -> 0.016020788 | P23: 46171 | Q23: =+WORKDAY.INTL(P23,-10,1,Feriados!$A$2:$A$1048576) -> 46156 | R23: =+VLOOKUP(A23,[1]CER_implicito!$A:$G,7) -> 738.52965 | S23: =+(R23/C23)^(30/(Q23-B23))-1 -> 0.019172159 | T23: =+T22 -> 46507 | U23: =+U22 -> 46493 | V23: =+VLOOKUP(A23,[1]CER_implicito!$A:$G,5) -> 871.39922 | W23: =+(V23/C23)^(30/(U23-B23))-1 -> 0.015966164
A24: =+[1]CER_implicito!$A441 -> 46007 | B24: 46037 | C24: =+VLOOKUP(B24,'Sheet1 (2)'!A:C,3) -> 684.94019 | H24: 46202 | I24: =+WORKDAY.INTL(H24,-10,1,Feriados!$A$2:$A$1048576) -> 46184 | J24: =+VLOOKUP(A24,[1]CER_implicito!$A:$G,4) -> 753.83229 | K24: =+(J24/C24)^(30/(I24-B24))-1 -> 0.019751384 | L24: 46324 | M24: =+WORKDAY.INTL(L24,-10,1,Feriados!$A$2:$A$1048576) -> 46310 | N24: =+VLOOKUP(A24,[1]CER_implicito!$A:$G,6) -> 799.08227 | O24: =+(N24/C24)^(30/(M24-B24))-1 -> 0.017081879 | P24: 46171 | Q24: =+WORKDAY.INTL(P24,-10,1,Feriados!$A$2:$A$1048576) -> 46156 | R24: =+VLOOKUP(A24,[1]CER_implicito!$A:$G,7) -> 741.32088 | S24: =+(R24/C24)^(30/(Q24-B24))-1 -> 0.020141859 | T24: =+T23 -> 46507 | U24: =+U23 -> 46493 | V24: =+VLOOKUP(A24,[1]CER_implicito!$A:$G,5) -> 873.41107 | W24: =+(V24/C24)^(30/(U24-B24))-1 -> 0.016120315
A25: =+[1]CER_implicito!$A442 -> 46008 | B25: 46037 | C25: =+VLOOKUP(B25,'Sheet1 (2)'!A:C,3) -> 684.94019 | H25: 46202 | I25: =+WORKDAY.INTL(H25,-10,1,Feriados!$A$2:$A$1048576) -> 46184 | J25: =+VLOOKUP(A25,[1]CER_implicito!$A:$G,4) -> 755.00394 | K25: =+(J25/C25)^(30/(I25-B25))-1 -> 0.020074645 | L25: 46324 | M25: =+WORKDAY.INTL(L25,-10,1,Feriados!$A$2:$A$1048576) -> 46310 | N25: =+VLOOKUP(A25,[1]CER_implicito!$A:$G,6) -> 795.17525 | O25: =+(N25/C25)^(30/(M25-B25))-1 -> 0.016534215 | P25: 46171 | Q25: =+WORKDAY.INTL(P25,-10,1,Feriados!$A$2:$A$1048576) -> 46156 | R25: =+VLOOKUP(A25,[1]CER_implicito!$A:$G,7) -> 743.01403 | S25: =+(R25/C25)^(30/(Q25-B25))-1 -> 0.020728744 | T25: =+T24 -> 46507 | U25: =+U24 -> 46493 | V25: =+VLOOKUP(A25,[1]CER_implicito!$A:$G,5) -> 876.51995 | W25: =+(V25/C25)^(30/(U25-B25))-1 -> 0.016357871
A26: =+[1]CER_implicito!$A443 -> 46009 | B26: 46037 | C26: =+VLOOKUP(B26,'Sheet1 (2)'!A:C,3) -> 684.94019 | H26: 46202 | I26: =+WORKDAY.INTL(H26,-10,1,Feriados!$A$2:$A$1048576) -> 46184 | J26: =+VLOOKUP(A26,[1]CER_implicito!$A:$G,4) -> 758.01197 | K26: =+(J26/C26)^(30/(I26-B26))-1 -> 0.020902741 | L26: 46324 | M26: =+WORKDAY.INTL(L26,-10,1,Feriados!$A$2:$A$1048576) -> 46310 | N26: =+VLOOKUP(A26,[1]CER_implicito!$A:$G,6) -> 798.28517 | O26: =+(N26/C26)^(30/(M26-B26))-1 -> 0.016970341 | P26: 46171 | Q26: =+WORKDAY.INTL(P26,-10,1,Feriados!$A$2:$A$1048576) -> 46156 | R26: =+VLOOKUP(A26,[1]CER_implicito!$A:$G,7) -> 743.3927 | S26: =+(R26/C26)^(30/(Q26-B26))-1 -> 0.020859862 | T26: =+T25 -> 46507 | U26: =+U25 -> 46493 | V26: =+VLOOKUP(A26,[1]CER_implicito!$A:$G,5) -> 877.13485 | W26: =+(V26/C26)^(30/(U26-B26))-1 -> 0.016404764
A27: =+[1]CER_implicito!$A444 -> 46010 | B27: 46037 | C27: =+VLOOKUP(B27,'Sheet1 (2)'!A:C,3) -> 684.94019 | H27: 46202 | I27: =+WORKDAY.INTL(H27,-10,1,Feriados!$A$2:$A$1048576) -> 46184 | J27: =+VLOOKUP(A27,[1]CER_implicito!$A:$G,4) -> 758.78056 | K27: =+(J27/C27)^(30/(I27-B27))-1 -> 0.021113911 | L27: 46324 | M27: =+WORKDAY.INTL(L27,-10,1,Feriados!$A$2:$A$1048576) -> 46310 | N27: =+VLOOKUP(A27,[1]CER_implicito!$A:$G,6) -> 800.89858 | O27: =+(N27/C27)^(30/(M27-B27))-1 -> 0.01733567 | P27: 46171 | Q27: =+WORKDAY.INTL(P27,-10,1,Feriados!$A$2:$A$1048576) -> 46156 | R27: =+VLOOKUP(A27,[1]CER_implicito!$A:$G,7) -> 743.34709 | S27: =+(R27/C27)^(30/(Q27-B27))-1 -> 0.020844073 | T27: =+T26 -> 46507 | U27: =+U26 -> 46493 | V27: =+VLOOKUP(A27,[1]CER_implicito!$A:$G,5) -> 879.13465 | W27: =+(V27/C27)^(30/(U27-B27))-1 -> 0.016557057
A28: =+[1]CER_implicito!$A445 -> 46013 | B28: 46037 | C28: =+VLOOKUP(B28,'Sheet1 (2)'!A:C,3) -> 684.94019 | H28: 46202 | I28: =+WORKDAY.INTL(H28,-10,1,Feriados!$A$2:$A$1048576) -> 46184 | J28: =+VLOOKUP(A28,[1]CER_implicito!$A:$G,4) -> 758.75674 | K28: =+(J28/C28)^(30/(I28-B28))-1 -> 0.021107371 | L28: 46324 | M28: =+WORKDAY.INTL(L28,-10,1,Feriados!$A$2:$A$1048576) -> 46310 | N28: =+VLOOKUP(A28,[1]CER_implicito!$A:$G,6) -> 800.20918 | O28: =+(N28/C28)^(30/(M28-B28))-1 -> 0.017239401 | P28: 46171 | Q28: =+WORKDAY.INTL(P28,-10,1,Feriados!$A$2:$A$1048576) -> 46156 | R28: =+VLOOKUP(A28,[1]CER_implicito!$A:$G,7) -> 742.52286 | S28: =+(R28/C28)^(30/(Q28-B28))-1 -> 0.020558595 | T28: =+T27 -> 46507 | U28: =+U27 -> 46493 | V28: =+VLOOKUP(A28,[1]CER_implicito!$A:$G,5) -> 874.51665 | W28: =+(V28/C28)^(30/(U28-B28))-1 -> 0.016204886
A29: =+[1]CER_implicito!$A446 -> 46014 | B29: 46037 | C29: =+VLOOKUP(B29,'Sheet1 (2)'!A:C,3) -> 684.94019 | H29: 46202 | I29: =+WORKDAY.INTL(H29,-10,1,Feriados!$A$2:$A$1048576) -> 46184 | J29: =+VLOOKUP(A29,[1]CER_implicito!$A:$G,4) -> 758.44981 | K29: =+(J29/C29)^(30/(I29-B29))-1 -> 0.021023059 | L29: 46324 | M29: =+WORKDAY.INTL(L29,-10,1,Feriados!$A$2:$A$1048576) -> 46310 | N29: =+VLOOKUP(A29,[1]CER_implicito!$A:$G,6) -> 801.30311 | O29: =+(N29/C29)^(30/(M29-B29))-1 -> 0.017392125 | P29: 46171 | Q29: =+WORKDAY.INTL(P29,-10,1,Feriados!$A$2:$A$1048576) -> 46156 | R29: =+VLOOKUP(A29,[1]CER_implicito!$A:$G,7) -> 744.63794 | S29: =+(R29/C29)^(30/(Q29-B29))-1 -> 0.021290689 | T29: =+T28 -> 46507 | U29: =+U28 -> 46493 | V29: =+VLOOKUP(A29,[1]CER_implicito!$A:$G,5) -> 876.94278 | W29: =+(V29/C29)^(30/(U29-B29))-1 -> 0.01639012
A30: =+[1]CER_implicito!$A447 -> 46015 | B30: 46037 | C30: =+VLOOKUP(B30,'Sheet1 (2)'!A:C,3) -> 684.94019 | H30: 46202 | I30: =+WORKDAY.INTL(H30,-10,1,Feriados!$A$2:$A$1048576) -> 46184 | J30: =+VLOOKUP(A30,[1]CER_implicito!$A:$G,4) -> 760.05033 | K30: =+(J30/C30)^(30/(I30-B30))-1 -> 0.021462409 | L30: 46324 | M30: =+WORKDAY.INTL(L30,-10,1,Feriados!$A$2:$A$1048576) -> 46310 | N30: =+VLOOKUP(A30,[1]CER_implicito!$A:$G,6) -> 797.53077 | O30: =+(N30/C30)^(30/(M30-B30))-1 -> 0.016864684 | P30: 46171 | Q30: =+WORKDAY.INTL(P30,-10,1,Feriados!$A$2:$A$1048576) -> 46156 | R30: =+VLOOKUP(A30,[1]CER_implicito!$A:$G,7) -> 748.71939 | S30: =+(R30/C30)^(30/(Q30-B30))-1 -> 0.02269902 | T30: =+T29 -> 46507 | U30: =+U29 -> 46493 | V30: =+VLOOKUP(A30,[1]CER_implicito!$A:$G,5) -> 883.29141 | W30: =+(V30/C30)^(30/(U30-B30))-1 -> 0.01687258
A31: =+[1]CER_implicito!$A448 -> 46017 | B31: 46037 | C31: =+VLOOKUP(B31,'Sheet1 (2)'!A:C,3) -> 684.94019 | D31: 46112 | E31: =+WORKDAY.INTL(D31,-10,1,Feriados!$A$2:$A$1048576) -> 46094 | F31: =+VLOOKUP(A31,[1]CER_implicito!$A:$G,3) -> 716.64555 | G31: =+(F31/C31)^(30/(E31-B31))-1 -> 0.024101569 | H31: 46202 | I31: =+WORKDAY.INTL(H31,-10,1,Feriados!$A$2:$A$1048576) -> 46184 | J31: =+VLOOKUP(A31,[1]CER_implicito!$A:$G,4) -> 758.91597 | K31: =+(J31/C31)^(30/(I31-B31))-1 -> 0.021151098 | L31: 46324 | M31: =+WORKDAY.INTL(L31,-10,1,Feriados!$A$2:$A$1048576) -> 46310 | N31: =+VLOOKUP(A31,[1]CER_implicito!$A:$G,6) -> 801.78195 | O31: =+(N31/C31)^(30/(M31-B31))-1 -> 0.017458916 | P31: 46171 | Q31: =+WORKDAY.INTL(P31,-10,1,Feriados!$A$2:$A$1048576) -> 46156 | R31: =+VLOOKUP(A31,[1]CER_implicito!$A:$G,7) -> 746.32848 | S31: =+(R31/C31)^(30/(Q31-B31))-1 -> 0.021874721 | T31: =+T30 -> 46507 | U31: =+U30 -> 46493 | V31: =+VLOOKUP(A31,[1]CER_implicito!$A:$G,5) -> 875.72231 | W31: =+(V31/C31)^(30/(U31-B31))-1 -> 0.016296997
A32: =+[1]CER_implicito!$A449 -> 46020 | B32: 46037 | C32: =+VLOOKUP(B32,'Sheet1 (2)'!A:C,3) -> 684.94019 | D32: =+D31 -> 46112 | E32: =+E31 -> 46094 | F32: =+VLOOKUP(A32,[1]CER_implicito!$A:$G,3) -> 713.85085 | G32: =+(F32/C32)^(30/(E32-B32))-1 -> 0.021997684 | H32: 46202 | I32: =+WORKDAY.INTL(H32,-10,1,Feriados!$A$2:$A$1048576) -> 46184 | J32: =+VLOOKUP(A32,[1]CER_implicito!$A:$G,4) -> 755.2018 | K32: =+(J32/C32)^(30/(I32-B32))-1 -> 0.020129195 | L32: 46324 | M32: =+WORKDAY.INTL(L32,-10,1,Feriados!$A$2:$A$1048576) -> 46310 | N32: =+VLOOKUP(A32,[1]CER_implicito!$A:$G,6) -> 799.63678 | O32: =+(N32/C32)^(30/(M32-B32))-1 -> 0.017159416 | P32: 46171 | Q32: =+WORKDAY.INTL(P32,-10,1,Feriados!$A$2:$A$1048576) -> 46156 | R32: =+VLOOKUP(A32,[1]CER_implicito!$A:$G,7) -> 743.68981 | S32: =+(R32/C32)^(30/(Q32-B32))-1 -> 0.020962704 | T32: =+T31 -> 46507 | U32: =+U31 -> 46493 | V32: =+VLOOKUP(A32,[1]CER_implicito!$A:$G,5) -> 881.0239 | W32: =+(V32/C32)^(30/(U32-B32))-1 -> 0.016700635
A33: =+[1]CER_implicito!$A450 -> 46021 | B33: 46037 | C33: =+VLOOKUP(B33,'Sheet1 (2)'!A:C,3) -> 684.94019 | D33: 46112 | E33: =+WORKDAY.INTL(D33,-10,1,Feriados!$A$2:$A$1048576) -> 46094 | F33: =+VLOOKUP(A33,[1]CER_implicito!$A:$G,3) -> 716.73926 | G33: =+(F33/C33)^(30/(E33-B33))-1 -> 0.02417205 | H33: 46202 | I33: =+WORKDAY.INTL(H33,-10,1,Feriados!$A$2:$A$1048576) -> 46184 | J33: =+VLOOKUP(A33,[1]CER_implicito!$A:$G,4) -> 757.52009 | K33: =+(J33/C33)^(30/(I33-B33))-1 -> 0.020767511 | L33: 46324 | M33: =+WORKDAY.INTL(L33,-10,1,Feriados!$A$2:$A$1048576) -> 46310 | N33: =+VLOOKUP(A33,[1]CER_implicito!$A:$G,6) -> 795.62831 | O33: =+(N33/C33)^(30/(M33-B33))-1 -> 0.016597845 | P33: 46171 | Q33: =+WORKDAY.INTL(P33,-10,1,Feriados!$A$2:$A$1048576) -> 46156 | R33: =+VLOOKUP(A33,[1]CER_implicito!$A:$G,7) -> 746.42978 | S33: =+(R33/C33)^(30/(Q33-B33))-1 -> 0.021909686 | T33: =+T32 -> 46507 | U33: =+U32 -> 46493 | V33: =+VLOOKUP(A33,[1]CER_implicito!$A:$G,5) -> 875.19452 | W33: =+(V33/C33)^(30/(U33-B33))-1 -> 0.016256689
A34: =+[1]CER_implicito!$A451 -> 46024 | B34: 46037 | C34: =+VLOOKUP(B34,'Sheet1 (2)'!A:C,3) -> 684.94019 | D34: 46112 | E34: =+E33 -> 46094 | F34: =+VLOOKUP(A34,[1]CER_implicito!$A:$G,3) -> 715.20295 | G34: =+(F34/C34)^(30/(E34-B34))-1 -> 0.023016051 | H34: 46202 | I34: =+WORKDAY.INTL(H34,-10,1,Feriados!$A$2:$A$1048576) -> 46184 | J34: =+VLOOKUP(A34,[1]CER_implicito!$A:$G,4) -> 756.45809 | K34: =+(J34/C34)^(30/(I34-B34))-1 -> 0.020475293 | L34: 46324 | M34: =+WORKDAY.INTL(L34,-10,1,Feriados!$A$2:$A$1048576) -> 46310 | N34: =+VLOOKUP(A34,[1]CER_implicito!$A:$G,6) -> 802.34405 | O34: =+(N34/C34)^(30/(M34-B34))-1 -> 0.017537277 | P34: 46171 | Q34: =+WORKDAY.INTL(P34,-10,1,Feriados!$A$2:$A$1048576) -> 46156 | R34: =+VLOOKUP(A34,[1]CER_implicito!$A:$G,7) -> 745.65466 | S34: =+(R34/C34)^(30/(Q34-B34))-1 -> 0.021642054 | T34: =+T33 -> 46507 | U34: =+U33 -> 46493 | V34: =+VLOOKUP(A34,[1]CER_implicito!$A:$G,5) -> 885.22705 | W34: =+(V34/C34)^(30/(U34-B34))-1 -> 0.017019034
A35: =+[1]CER_implicito!$A452 -> 46027 | B35: 46037 | C35: =+VLOOKUP(B35,'Sheet1 (2)'!A:C,3) -> 684.94019 | D35: 46112 | E35: =+WORKDAY.INTL(D35,-10,1,Feriados!$A$2:$A$1048576) -> 46094 | F35: =+VLOOKUP(A35,[1]CER_implicito!$A:$G,3) -> 716.14336 | G35: =+(F35/C35)^(30/(E35-B35))-1 -> 0.023723804 | H35: 46202 | I35: =+WORKDAY.INTL(H35,-10,1,Feriados!$A$2:$A$1048576) -> 46184 | J35: =+VLOOKUP(A35,[1]CER_implicito!$A:$G,4) -> 756.12386 | K35: =+(J35/C35)^(30/(I35-B35))-1 -> 0.02038326 | L35: 46324 | M35: =+WORKDAY.INTL(L35,-10,1,Feriados!$A$2:$A$1048576) -> 46310 | N35: =+VLOOKUP(A35,[1]CER_implicito!$A:$G,6) -> 807.67082 | O35: =+(N35/C35)^(30/(M35-B35))-1 -> 0.018277448 | P35: 46171 | Q35: =+WORKDAY.INTL(P35,-10,1,Feriados!$A$2:$A$1048576) -> 46156 | R35: =+VLOOKUP(A35,[1]CER_implicito!$A:$G,7) -> 743.60122 | S35: =+(R35/C35)^(30/(Q35-B35))-1 -> 0.020932044 | T35: =+T34 -> 46507 | U35: =+U34 -> 46493 | V35: =+VLOOKUP(A35,[1]CER_implicito!$A:$G,5) -> 885.01973 | W35: =+(V35/C35)^(30/(U35-B35))-1 -> 0.017003362
A36: =+[1]CER_implicito!$A453 -> 46028 | B36: 46037 | C36: =+VLOOKUP(B36,'Sheet1 (2)'!A:C,3) -> 684.94019 | D36: 46112 | E36: =+E35 -> 46094 | F36: =+VLOOKUP(A36,[1]CER_implicito!$A:$G,3) -> 716.27877 | G36: =+(F36/C36)^(30/(E36-B36))-1 -> 0.023825677 | H36: 46202 | I36: =+WORKDAY.INTL(H36,-10,1,Feriados!$A$2:$A$1048576) -> 46184 | J36: =+VLOOKUP(A36,[1]CER_implicito!$A:$G,4) -> 756.5812 | K36: =+(J36/C36)^(30/(I36-B36))-1 -> 0.020509184 | L36: 46324 | M36: =+WORKDAY.INTL(L36,-10,1,Feriados!$A$2:$A$1048576) -> 46310 | N36: =+VLOOKUP(A36,[1]CER_implicito!$A:$G,6) -> 811.69921 | O36: =+(N36/C36)^(30/(M36-B36))-1 -> 0.018834326 | P36: 46171 | Q36: =+WORKDAY.INTL(P36,-10,1,Feriados!$A$2:$A$1048576) -> 46156 | R36: =+VLOOKUP(A36,[1]CER_implicito!$A:$G,7) -> 742.97856 | S36: =+(R36/C36)^(30/(Q36-B36))-1 -> 0.02071646 | T36: =+T35 -> 46507 | U36: =+U35 -> 46493 | V36: =+VLOOKUP(A36,[1]CER_implicito!$A:$G,5) -> 884.98646 | W36: =+(V36/C36)^(30/(U36-B36))-1 -> 0.017000847
A37: =+[1]CER_implicito!$A454 -> 46029 | B37: 46037 | C37: =+VLOOKUP(B37,'Sheet1 (2)'!A:C,3) -> 684.94019 | D37: 46112 | E37: =+WORKDAY.INTL(D37,-10,1,Feriados!$A$2:$A$1048576) -> 46094 | F37: =+VLOOKUP(A37,[1]CER_implicito!$A:$G,3) -> 716.20246 | G37: =+(F37/C37)^(30/(E37-B37))-1 -> 0.023768267 | H37: 46202 | I37: =+WORKDAY.INTL(H37,-10,1,Feriados!$A$2:$A$1048576) -> 46184 | J37: =+VLOOKUP(A37,[1]CER_implicito!$A:$G,4) -> 758.42493 | K37: =+(J37/C37)^(30/(I37-B37))-1 -> 0.021016224 | L37: 46324 | M37: =+WORKDAY.INTL(L37,-10,1,Feriados!$A$2:$A$1048576) -> 46310 | N37: =+VLOOKUP(A37,[1]CER_implicito!$A:$G,6) -> 810.8678 | O37: =+(N37/C37)^(30/(M37-B37))-1 -> 0.018719596 | P37: 46171 | Q37: =+WORKDAY.INTL(P37,-10,1,Feriados!$A$2:$A$1048576) -> 46156 | R37: =+VLOOKUP(A37,[1]CER_implicito!$A:$G,7) -> 747.30031 | S37: =+(R37/C37)^(30/(Q37-B37))-1 -> 0.02221001 | T37: =+T36 -> 46507 | U37: =+U36 -> 46493 | V37: =+VLOOKUP(A37,[1]CER_implicito!$A:$G,5) -> 884.95023 | W37: =+(V37/C37)^(30/(U37-B37))-1 -> 0.016998107
A38: =+[1]CER_implicito!$A455 -> 46030 | B38: 46037 | C38: =+VLOOKUP(B38,'Sheet1 (2)'!A:C,3) -> 684.94019 | D38: 46112 | E38: =+E37 -> 46094 | F38: =+VLOOKUP(A38,[1]CER_implicito!$A:$G,3) -> 716.70003 | G38: =+(F38/C38)^(30/(E38-B38))-1 -> 0.024142547 | H38: 46202 | I38: =+WORKDAY.INTL(H38,-10,1,Feriados!$A$2:$A$1048576) -> 46184 | J38: =+VLOOKUP(A38,[1]CER_implicito!$A:$G,4) -> 759.08263 | K38: =+(J38/C38)^(30/(I38-B38))-1 -> 0.02119686 | L38: 46324 | M38: =+WORKDAY.INTL(L38,-10,1,Feriados!$A$2:$A$1048576) -> 46310 | N38: =+VLOOKUP(A38,[1]CER_implicito!$A:$G,6) -> 810.54381 | O38: =+(N38/C38)^(30/(M38-B38))-1 -> 0.018674858 | P38: 46171 | Q38: =+WORKDAY.INTL(P38,-10,1,Feriados!$A$2:$A$1048576) -> 46156 | R38: =+VLOOKUP(A38,[1]CER_implicito!$A:$G,7) -> 746.30786 | S38: =+(R38/C38)^(30/(Q38-B38))-1 -> 0.021867602 | T38: =+T37 -> 46507 | U38: =+U37 -> 46493 | V38: =+VLOOKUP(A38,[1]CER_implicito!$A:$G,5) -> 885.51874 | W38: =+(V38/C38)^(30/(U38-B38))-1 -> 0.017041078
A39: =+[1]CER_implicito!$A456 -> 46031 | B39: 46037 | C39: =+VLOOKUP(B39,'Sheet1 (2)'!A:C,3) -> 684.94019 | D39: 46112 | E39: =+WORKDAY.INTL(D39,-10,1,Feriados!$A$2:$A$1048576) -> 46094 | F39: =+VLOOKUP(A39,[1]CER_implicito!$A:$G,3) -> 718.89297 | G39: =+(F39/C39)^(30/(E39-B39))-1 -> 0.02579064 | H39: 46202 | I39: =+WORKDAY.INTL(H39,-10,1,Feriados!$A$2:$A$1048576) -> 46184 | J39: =+VLOOKUP(A39,[1]CER_implicito!$A:$G,4) -> 764.31618 | K39: =+(J39/C39)^(30/(I39-B39))-1 -> 0.022629813 | L39: 46324 | M39: =+WORKDAY.INTL(L39,-10,1,Feriados!$A$2:$A$1048576) -> 46310 | N39: =+VLOOKUP(A39,[1]CER_implicito!$A:$G,6) -> 816.27809 | O39: =+(N39/C39)^(30/(M39-B39))-1 -> 0.019464324 | P39: 46171 | Q39: =+WORKDAY.INTL(P39,-10,1,Feriados!$A$2:$A$1048576) -> 46156 | R39: =+VLOOKUP(A39,[1]CER_implicito!$A:$G,7) -> 749.64419 | S39: =+(R39/C39)^(30/(Q39-B39))-1 -> 0.023017329 | T39: =+T38 -> 46507 | U39: =+U38 -> 46493 | V39: =+VLOOKUP(A39,[1]CER_implicito!$A:$G,5) -> 890.1926 | W39: =+(V39/C39)^(30/(U39-B39))-1 -> 0.01739337
A40: =+[1]CER_implicito!$A457 -> 46034 | B40: 46037 | C40: =+VLOOKUP(B40,'Sheet1 (2)'!A:C,3) -> 684.94019 | D40: 46112 | E40: =+E39 -> 46094 | F40: =+VLOOKUP(A40,[1]CER_implicito!$A:$G,3) -> 717.36475 | G40: =+(F40/C40)^(30/(E40-B40))-1 -> 0.024642366 | H40: 46202 | I40: =+WORKDAY.INTL(H40,-10,1,Feriados!$A$2:$A$1048576) -> 46184 | J40: =+VLOOKUP(A40,[1]CER_implicito!$A:$G,4) -> 765.30477 | K40: =+(J40/C40)^(30/(I40-B40))-1 -> 0.022899615 | L40: 46324 | M40: =+WORKDAY.INTL(L40,-10,1,Feriados!$A$2:$A$1048576) -> 46310 | N40: =+VLOOKUP(A40,[1]CER_implicito!$A:$G,6) -> 813.28386 | O40: =+(N40/C40)^(30/(M40-B40))-1 -> 0.019052711 | P40: 46171 | Q40: =+WORKDAY.INTL(P40,-10,1,Feriados!$A$2:$A$1048576) -> 46156 | R40: =+VLOOKUP(A40,[1]CER_implicito!$A:$G,7) -> 748.66842 | S40: =+(R40/C40)^(30/(Q40-B40))-1 -> 0.022681467 | T40: =+T39 -> 46507 | U40: =+U39 -> 46493 | V40: =+VLOOKUP(A40,[1]CER_implicito!$A:$G,5) -> 891.96068 | W40: =+(V40/C40)^(30/(U40-B40))-1 -> 0.01752619
A41: =+[1]CER_implicito!$A458 -> 46035 | B41: 46037 | C41: =+VLOOKUP(B41,'Sheet1 (2)'!A:C,3) -> 684.94019 | D41: 46112 | E41: =+WORKDAY.INTL(D41,-10,1,Feriados!$A$2:$A$1048576) -> 46094 | F41: =+VLOOKUP(A41,[1]CER_implicito!$A:$G,3) -> 719.56874 | G41: =+(F41/C41)^(30/(E41-B41))-1 -> 0.026298031 | H41: 46202 | I41: =+WORKDAY.INTL(H41,-10,1,Feriados!$A$2:$A$1048576) -> 46184 | J41: =+VLOOKUP(A41,[1]CER_implicito!$A:$G,4) -> 766.03342 | K41: =+(J41/C41)^(30/(I41-B41))-1 -> 0.023098296 | L41: 46324 | M41: =+WORKDAY.INTL(L41,-10,1,Feriados!$A$2:$A$1048576) -> 46310 | N41: =+VLOOKUP(A41,[1]CER_implicito!$A:$G,6) -> 815.82023 | O41: =+(N41/C41)^(30/(M41-B41))-1 -> 0.019401469 | P41: 46171 | Q41: =+WORKDAY.INTL(P41,-10,1,Feriados!$A$2:$A$1048576) -> 46156 | R41: =+VLOOKUP(A41,[1]CER_implicito!$A:$G,7) -> 751.74175 | S41: =+(R41/C41)^(30/(Q41-B41))-1 -> 0.023738212 | T41: =+T40 -> 46507 | U41: =+U40 -> 46493 | V41: =+VLOOKUP(A41,[1]CER_implicito!$A:$G,5) -> 895.1788 | W41: =+(V41/C41)^(30/(U41-B41))-1 -> 0.017767307
A42: =+[1]CER_implicito!$A459 -> 46036 | B42: 46037 | C42: =+VLOOKUP(B42,'Sheet1 (2)'!A:C,3) -> 684.94019 | D42: 46112 | E42: =+E41 -> 46094 | F42: =+VLOOKUP(A42,[1]CER_implicito!$A:$G,3) -> 719.77817 | G42: =+(F42/C42)^(30/(E42-B42))-1 -> 0.026455226 | H42: 46202 | I42: =+WORKDAY.INTL(H42,-10,1,Feriados!$A$2:$A$1048576) -> 46184 | J42: =+VLOOKUP(A42,[1]CER_implicito!$A:$G,4) -> 765.16612 | K42: =+(J42/C42)^(30/(I42-B42))-1 -> 0.022861791 | L42: 46324 | M42: =+WORKDAY.INTL(L42,-10,1,Feriados!$A$2:$A$1048576) -> 46310 | N42: =+VLOOKUP(A42,[1]CER_implicito!$A:$G,6) -> 815.2103 | O42: =+(N42/C42)^(30/(M42-B42))-1 -> 0.019317691 | P42: 46171 | Q42: =+WORKDAY.INTL(P42,-10,1,Feriados!$A$2:$A$1048576) -> 46156 | R42: =+VLOOKUP(A42,[1]CER_implicito!$A:$G,7) -> 751.78007 | S42: =+(R42/C42)^(30/(Q42-B42))-1 -> 0.023751366 | T42: =+T41 -> 46507 | U42: =+U41 -> 46493 | V42: =+VLOOKUP(A42,[1]CER_implicito!$A:$G,5) -> 893.68772 | W42: =+(V42/C42)^(30/(U42-B42))-1 -> 0.017655688
A43: =+[1]CER_implicito!$A460 -> 46037 | B43: 46068 | C43: =+VLOOKUP(B43,'Sheet1 (2)'!A:C,3) -> 704.11851 | D43: 46112 | E43: =+WORKDAY.INTL(D43,-10,1,Feriados!$A$2:$A$1048576) -> 46094 | F43: =+VLOOKUP(A43,[1]CER_implicito!$A:$G,3) -> 720.00405 | G43: =+(F43/C43)^(30/(E43-B43))-1 -> 0.02607668 | H43: 46202 | I43: =+WORKDAY.INTL(H43,-10,1,Feriados!$A$2:$A$1048576) -> 46184 | J43: =+VLOOKUP(A43,[1]CER_implicito!$A:$G,4) -> 766.54648 | K43: =+(J43/C43)^(30/(I43-B43))-1 -> 0.022212585 | L43: 46324 | M43: =+WORKDAY.INTL(L43,-10,1,Feriados!$A$2:$A$1048576) -> 46310 | N43: =+VLOOKUP(A43,[1]CER_implicito!$A:$G,6) -> 812.66992 | O43: =+(N43/C43)^(30/(M43-B43))-1 -> 0.017933075 | P43: 46171 | Q43: =+WORKDAY.INTL(P43,-10,1,Feriados!$A$2:$A$1048576) -> 46156 | R43: =+VLOOKUP(A43,[1]CER_implicito!$A:$G,7) -> 752.03997 | S43: =+(R43/C43)^(30/(Q43-B43))-1 -> 0.022700221 | T43: =+T42 -> 46507 | U43: =+U42 -> 46493 | V43: =+VLOOKUP(A43,[1]CER_implicito!$A:$G,5) -> 888.10965 | W43: =+(V43/C43)^(30/(U43-B43))-1 -> 0.016521958
A44: =+[1]CER_implicito!$A461 -> 46038 | B44: 46068 | C44: =+VLOOKUP(B44,'Sheet1 (2)'!A:C,3) -> 704.11851 | D44: 46112 | E44: =+E43 -> 46094 | F44: =+VLOOKUP(A44,[1]CER_implicito!$A:$G,3) -> 720.07436 | G44: =+(F44/C44)^(30/(E44-B44))-1 -> 0.026192296 | H44: 46202 | I44: =+WORKDAY.INTL(H44,-10,1,Feriados!$A$2:$A$1048576) -> 46184 | J44: =+VLOOKUP(A44,[1]CER_implicito!$A:$G,4) -> 767.64327 | K44: =+(J44/C44)^(30/(I44-B44))-1 -> 0.022590644 | L44: 46324 | M44: =+WORKDAY.INTL(L44,-10,1,Feriados!$A$2:$A$1048576) -> 46310 | N44: =+VLOOKUP(A44,[1]CER_implicito!$A:$G,6) -> 814.97391 | O44: =+(N44/C44)^(30/(M44-B44))-1 -> 0.018290392 | P44: 46171 | Q44: =+WORKDAY.INTL(P44,-10,1,Feriados!$A$2:$A$1048576) -> 46156 | R44: =+VLOOKUP(A44,[1]CER_implicito!$A:$G,7) -> 754.50009 | S44: =+(R44/C44)^(30/(Q44-B44))-1 -> 0.023839512 | T44: =+T43 -> 46507 | U44: =+U43 -> 46493 | V44: =+VLOOKUP(A44,[1]CER_implicito!$A:$G,5) -> 886.05277 | W44: =+(V44/C44)^(30/(U44-B44))-1 -> 0.016355593
...

Sheet Serie infla anual
A1: Fecha | B1: 45992 | C1: 46023 | D1: 46054 | E1: 46082 | F1: 46113 | G1: 46143 | H1: 46174 | I1: 46204 | J1: 46235 | K1: 46266 | L1: 46296 | M1: 46327 | N1: 46357 | O1: 46388 | P1: Inflación anual
A2: =+'Inflación BE'!A31 -> 46017 | B2: =+VLOOKUP(A2,'Inflación BE'!A:G,7) -> 0.024101569 | C2: =+VLOOKUP(A2,'Inflación BE'!A:G,7) -> 0.024101569 | D2: =+VLOOKUP(A2,'Inflación BE'!A:S,19) -> 0.021874721 | E2: =+D2 -> 0.021874721 | F2: =+((((1+VLOOKUP(A2,'Inflación BE'!A:K,11))^3)/((1+E2)^2))^(1/1))-1 -> 0.01970539 | G2: =+((((1+VLOOKUP(A2,'Inflación BE'!A:O,15))^7)/((1+VLOOKUP(A2,'Inflación BE'!A:K,11))^3))^(1/4))-1 -> 0.014698543 | H2: =+G2 -> 0.014698543 | I2: =+H2 -> 0.014698543 | J2: =+I2 -> 0.014698543 | K2: =+((((1+VLOOKUP(A2,'Inflación BE'!A:W,23))^12)/((1+VLOOKUP(A2,'Inflación BE'!A:O,15))^7))^(1/5))-1 -> 0.01467254 | L2: =+K2 -> 0.01467254 | M2: =+L2 -> 0.01467254 | N2: =+M2 -> 0.01467254 | O2: =+N2 -> 0.01467254 | P2: =+((1+C2)*(1+D2)*(1+E2)*(1+F2)*(1+G2)*(1+H2)*(1+I2)*(1+J2)*(1+K2)*(1+L2)*(1+M2)*(1+N2))-1 -> 0.2253632
A3: =+'Inflación BE'!A32 -> 46020 | B3: =+VLOOKUP(A3,'Inflación BE'!A:G,7) -> 0.021997684 | C3: =+VLOOKUP(A3,'Inflación BE'!A:G,7) -> 0.021997684 | D3: =+VLOOKUP(A3,'Inflación BE'!A:S,19) -> 0.020962704 | E3: =+D3 -> 0.020962704 | F3: =+((((1+VLOOKUP(A3,'Inflación BE'!A:K,11))^3)/((1+E3)^2))^(1/1))-1 -> 0.018464219 | G3: =+((((1+VLOOKUP(A3,'Inflación BE'!A:O,15))^7)/((1+VLOOKUP(A3,'Inflación BE'!A:K,11))^3))^(1/4))-1 -> 0.014937756 | H3: =+G3 -> 0.014937756 | I3: =+H3 -> 0.014937756 | J3: =+I3 -> 0.014937756 | K3: =+((((1+VLOOKUP(A3,'Inflación BE'!A:W,23))^12)/((1+VLOOKUP(A3,'Inflación BE'!A:O,15))^7))^(1/5))-1 -> 0.01605869 | L3: =+K3 -> 0.01605869 | M3: =+L3 -> 0.01605869 | N3: =+M3 -> 0.01605869 | O3: =+N3 -> 0.01605869 | P3: =+((1+C3)*(1+D3)*(1+E3)*(1+F3)*(1+G3)*(1+H3)*(1+I3)*(1+J3)*(1+K3)*(1+L3)*(1+M3)*(1+N3))-1 -> 0.22701043
A4: =+'Inflación BE'!A33 -> 46021 | B4: =+VLOOKUP(A4,'Inflación BE'!A:G,7) -> 0.02417205 | C4: =+VLOOKUP(A4,'Inflación BE'!A:G,7) -> 0.02417205 | D4: =+VLOOKUP(A4,'Inflación BE'!A:S,19) -> 0.021909686 | E4: =+D4 -> 0.021909686 | F4: =+((((1+VLOOKUP(A4,'Inflación BE'!A:K,11))^3)/((1+E4)^2))^(1/1))-1 -> 0.018486989 | G4: =+((((1+VLOOKUP(A4,'Inflación BE'!A:O,15))^7)/((1+VLOOKUP(A4,'Inflación BE'!A:K,11))^3))^(1/4))-1 -> 0.013481777 | H4: =+G4 -> 0.013481777 | I4: =+H4 -> 0.013481777 | J4: =+I4 -> 0.013481777 | K4: =+((((1+VLOOKUP(A4,'Inflación BE'!A:W,23))^12)/((1+VLOOKUP(A4,'Inflación BE'!A:O,15))^7))^(1/5))-1 -> 0.015779264 | L4: =+K4 -> 0.015779264 | M4: =+L4 -> 0.015779264 | N4: =+M4 -> 0.015779264 | O4: =+N4 -> 0.015779264 | P4: =+((1+C4)*(1+D4)*(1+E4)*(1+F4)*(1+G4)*(1+H4)*(1+I4)*(1+J4)*(1+K4)*(1+L4)*(1+M4)*(1+N4))-1 -> 0.22352989
A5: =+'Inflación BE'!A34 -> 46024 | B5: =+VLOOKUP(A5,'Inflación BE'!A:G,7) -> 0.023016051 | C5: =+VLOOKUP(A5,'Inflación BE'!A:G,7) -> 0.023016051 | D5: =+VLOOKUP(A5,'Inflación BE'!A:S,19) -> 0.021642054 | E5: =+D5 -> 0.021642054 | F5: =+((((1+VLOOKUP(A5,'Inflación BE'!A:K,11))^3)/((1+E5)^2))^(1/1))-1 -> 0.018145767 | G5: =+((((1+VLOOKUP(A5,'Inflación BE'!A:O,15))^7)/((1+VLOOKUP(A5,'Inflación BE'!A:K,11))^3))^(1/4))-1 -> 0.015339318 | H5: =+G5 -> 0.015339318 | I5: =+H5 -> 0.015339318 | J5: =+I5 -> 0.015339318 | K5: =+((((1+VLOOKUP(A5,'Inflación BE'!A:W,23))^12)/((1+VLOOKUP(A5,'Inflación BE'!A:O,15))^7))^(1/5))-1 -> 0.016293936 | L5: =+K5 -> 0.016293936 | M5: =+L5 -> 0.016293936 | N5: =+M5 -> 0.016293936 | O5: =+N5 -> 0.016293936 | P5: =+((1+C5)*(1+D5)*(1+E5)*(1+F5)*(1+G5)*(1+H5)*(1+I5)*(1+J5)*(1+K5)*(1+L5)*(1+M5)*(1+N5))-1 -> 0.23257139
A6: =+'Inflación BE'!A35 -> 46027 | B6: =+VLOOKUP(A6,'Inflación BE'!A:G,7) -> 0.023723804 | C6: =+VLOOKUP(A6,'Inflación BE'!A:G,7) -> 0.023723804 | D6: =+VLOOKUP(A6,'Inflación BE'!A:S,19) -> 0.020932044 | E6: =+D6 -> 0.020932044 | F6: =+((((1+VLOOKUP(A6,'Inflación BE'!A:K,11))^3)/((1+E6)^2))^(1/1))-1 -> 0.019286577 | G6: =+((((1+VLOOKUP(A6,'Inflación BE'!A:O,15))^7)/((1+VLOOKUP(A6,'Inflación BE'!A:K,11))^3))^(1/4))-1 -> 0.016700942 | H6: =+G6 -> 0.016700942 | I6: =+H6 -> 0.016700942 | J6: =+I6 -> 0.016700942 | K6: =+((((1+VLOOKUP(A6,'Inflación BE'!A:W,23))^12)/((1+VLOOKUP(A6,'Inflación BE'!A:O,15))^7))^(1/5))-1 -> 0.015222319 | L6: =+K6 -> 0.015222319 | M6: =+L6 -> 0.015222319 | N6: =+M6 -> 0.015222319 | O6: =+N6 -> 0.015222319 | P6: =+((1+C6)*(1+D6)*(1+E6)*(1+F6)*(1+G6)*(1+H6)*(1+I6)*(1+J6)*(1+K6)*(1+L6)*(1+M6)*(1+N6))-1 -> 0.23449776
A7: =+'Inflación BE'!A36 -> 46028 | B7: =+VLOOKUP(A7,'Inflación BE'!A:G,7) -> 0.023825677 | C7: =+VLOOKUP(A7,'Inflación BE'!A:G,7) -> 0.023825677 | D7: =+VLOOKUP(A7,'Inflación BE'!A:S,19) -> 0.02071646 | E7: =+D7 -> 0.02071646 | F7: =+((((1+VLOOKUP(A7,'Inflación BE'!A:K,11))^3)/((1+E7)^2))^(1/1))-1 -> 0.020094759 | G7: =+((((1+VLOOKUP(A7,'Inflación BE'!A:O,15))^7)/((1+VLOOKUP(A7,'Inflación BE'!A:K,11))^3))^(1/4))-1 -> 0.017579987 | H7: =+G7 -> 0.017579987 | I7: =+H7 -> 0.017579987 | J7: =+I7 -> 0.017579987 | K7: =+((((1+VLOOKUP(A7,'Inflación BE'!A:W,23))^12)/((1+VLOOKUP(A7,'Inflación BE'!A:O,15))^7))^(1/5))-1 -> 0.014439517 | L7: =+K7 -> 0.014439517 | M7: =+L7 -> 0.014439517 | N7: =+M7 -> 0.014439517 | O7: =+N7 -> 0.014439517 | P7: =+((1+C7)*(1+D7)*(1+E7)*(1+F7)*(1+G7)*(1+H7)*(1+I7)*(1+J7)*(1+K7)*(1+L7)*(1+M7)*(1+N7))-1 -> 0.23553665
A8: =+'Inflación BE'!A37 -> 46029 | B8: =+VLOOKUP(A8,'Inflación BE'!A:G,7) -> 0.023768267 | C8: =+VLOOKUP(A8,'Inflación BE'!A:G,7) -> 0.023768267 | D8: =+VLOOKUP(A8,'Inflación BE'!A:S,19) -> 0.02221001 | E8: =+D8 -> 0.02221001 | F8: =+((((1+VLOOKUP(A8,'Inflación BE'!A:K,11))^3)/((1+E8)^2))^(1/1))-1 -> 0.018632833 | G8: =+((((1+VLOOKUP(A8,'Inflación BE'!A:O,15))^7)/((1+VLOOKUP(A8,'Inflación BE'!A:K,11))^3))^(1/4))-1 -> 0.017000515 | H8: =+G8 -> 0.017000515 | I8: =+H8 -> 0.017000515 | J8: =+I8 -> 0.017000515 | K8: =+((((1+VLOOKUP(A8,'Inflación BE'!A:W,23))^12)/((1+VLOOKUP(A8,'Inflación BE'!A:O,15))^7))^(1/5))-1 -> 0.014592909 | L8: =+K8 -> 0.014592909 | M8: =+L8 -> 0.014592909 | N8: =+M8 -> 0.014592909 | O8: =+N8 -> 0.014592909 | P8: =+((1+C8)*(1+D8)*(1+E8)*(1+F8)*(1+G8)*(1+H8)*(1+I8)*(1+J8)*(1+K8)*(1+L8)*(1+M8)*(1+N8))-1 -> 0.23524065
A9: =+'Inflación BE'!A38 -> 46030 | B9: =+VLOOKUP(A9,'Inflación BE'!A:G,7) -> 0.024142547 | C9: =+VLOOKUP(A9,'Inflación BE'!A:G,7) -> 0.024142547 | D9: =+VLOOKUP(A9,'Inflación BE'!A:S,19) -> 0.021867602 | E9: =+D9 -> 0.021867602 | F9: =+((((1+VLOOKUP(A9,'Inflación BE'!A:K,11))^3)/((1+E9)^2))^(1/1))-1 -> 0.019856697 | G9: =+((((1+VLOOKUP(A9,'Inflación BE'!A:O,15))^7)/((1+VLOOKUP(A9,'Inflación BE'!A:K,11))^3))^(1/4))-1 -> 0.016787445 | H9: =+G9 -> 0.016787445 | I9: =+H9 -> 0.016787445 | J9: =+I9 -> 0.016787445 | K9: =+((((1+VLOOKUP(A9,'Inflación BE'!A:W,23))^12)/((1+VLOOKUP(A9,'Inflación BE'!A:O,15))^7))^(1/5))-1 -> 0.014758185 | L9: =+K9 -> 0.014758185 | M9: =+L9 -> 0.014758185 | N9: =+M9 -> 0.014758185 | O9: =+N9 -> 0.014758185 | P9: =+((1+C9)*(1+D9)*(1+E9)*(1+F9)*(1+G9)*(1+H9)*(1+I9)*(1+J9)*(1+K9)*(1+L9)*(1+M9)*(1+N9))-1 -> 0.23611756
A10: =+'Inflación BE'!A39 -> 46031 | B10: =+VLOOKUP(A10,'Inflación BE'!A:G,7) -> 0.02579064 | C10: =+VLOOKUP(A10,'Inflación BE'!A:G,7) -> 0.02579064 | D10: =+VLOOKUP(A10,'Inflación BE'!A:S,19) -> 0.023017329 | E10: =+D10 -> 0.023017329 | F10: =+((((1+VLOOKUP(A10,'Inflación BE'!A:K,11))^3)/((1+E10)^2))^(1/1))-1 -> 0.021855221 | G10: =+((((1+VLOOKUP(A10,'Inflación BE'!A:O,15))^7)/((1+VLOOKUP(A10,'Inflación BE'!A:K,11))^3))^(1/4))-1 -> 0.017096639 | H10: =+G10 -> 0.017096639 | I10: =+H10 -> 0.017096639 | J10: =+I10 -> 0.017096639 | K10: =+((((1+VLOOKUP(A10,'Inflación BE'!A:W,23))^12)/((1+VLOOKUP(A10,'Inflación BE'!A:O,15))^7))^(1/5))-1 -> 0.014501101 | L10: =+K10 -> 0.014501101 | M10: =+L10 -> 0.014501101 | N10: =+M10 -> 0.014501101 | O10: =+N10 -> 0.014501101 | P10: =+((1+C10)*(1+D10)*(1+E10)*(1+F10)*(1+G10)*(1+H10)*(1+I10)*(1+J10)*(1+K10)*(1+L10)*(1+M10)*(1+N10))-1 -> 0.24357805
A11: =+'Inflación BE'!A40 -> 46034 | B11: =+VLOOKUP(A11,'Inflación BE'!A:G,7) -> 0.024642366 | C11: =+VLOOKUP(A11,'Inflación BE'!A:G,7) -> 0.024642366 | D11: =+VLOOKUP(A11,'Inflación BE'!A:S,19) -> 0.022681467 | E11: =+D11 -> 0.022681467 | F11: =+((((1+VLOOKUP(A11,'Inflación BE'!A:K,11))^3)/((1+E11)^2))^(1/1))-1 -> 0.02333605 | G11: =+((((1+VLOOKUP(A11,'Inflación BE'!A:O,15))^7)/((1+VLOOKUP(A11,'Inflación BE'!A:K,11))^3))^(1/4))-1 -> 0.016177031 | H11: =+G11 -> 0.016177031 | I11: =+H11 -> 0.016177031 | J11: =+I11 -> 0.016177031 | K11: =+((((1+VLOOKUP(A11,'Inflación BE'!A:W,23))^12)/((1+VLOOKUP(A11,'Inflación BE'!A:O,15))^7))^(1/5))-1 -> 0.015392901 | L11: =+K11 -> 0.015392901 | M11: =+L11 -> 0.015392901 | N11: =+M11 -> 0.015392901 | O11: =+N11 -> 0.015392901 | P11: =+((1+C11)*(1+D11)*(1+E11)*(1+F11)*(1+G11)*(1+H11)*(1+I11)*(1+J11)*(1+K11)*(1+L11)*(1+M11)*(1+N11))-1 -> 0.24304068
A12: =+'Inflación BE'!A41 -> 46035 | B12: =+VLOOKUP(A12,'Inflación BE'!A:G,7) -> 0.026298031 | C12: =+VLOOKUP(A12,'Inflación BE'!A:G,7) -> 0.026298031 | D12: =+VLOOKUP(A12,'Inflación BE'!A:S,19) -> 0.023738212 | E12: =+D12 -> 0.023738212 | F12: =+((((1+VLOOKUP(A12,'Inflación BE'!A:K,11))^3)/((1+E12)^2))^(1/1))-1 -> 0.021819665 | G12: =+((((1+VLOOKUP(A12,'Inflación BE'!A:O,15))^7)/((1+VLOOKUP(A12,'Inflación BE'!A:K,11))^3))^(1/4))-1 -> 0.016637618 | H12: =+G12 -> 0.016637618 | I12: =+H12 -> 0.016637618 | J12: =+I12 -> 0.016637618 | K12: =+((((1+VLOOKUP(A12,'Inflación BE'!A:W,23))^12)/((1+VLOOKUP(A12,'Inflación BE'!A:O,15))^7))^(1/5))-1 -> 0.01548388 | L12: =+K12 -> 0.01548388 | M12: =+L12 -> 0.01548388 | N12: =+M12 -> 0.01548388 | O12: =+N12 -> 0.01548388 | P12: =+((1+C12)*(1+D12)*(1+E12)*(1+F12)*(1+G12)*(1+H12)*(1+I12)*(1+J12)*(1+K12)*(1+L12)*(1+M12)*(1+N12))-1 -> 0.24848237
A13: =+'Inflación BE'!A42 -> 46036 | B13: =+VLOOKUP(A13,'Inflación BE'!A:G,7) -> 0.026455226 | C13: =+VLOOKUP(A13,'Inflación BE'!A:G,7) -> 0.026455226 | D13: =+VLOOKUP(A13,'Inflación BE'!A:S,19) -> 0.023751366 | E13: =+D13 -> 0.023751366 | F13: =+((((1+VLOOKUP(A13,'Inflación BE'!A:K,11))^3)/((1+E13)^2))^(1/1))-1 -> 0.02108496 | G13: =+((((1+VLOOKUP(A13,'Inflación BE'!A:O,15))^7)/((1+VLOOKUP(A13,'Inflación BE'!A:K,11))^3))^(1/4))-1 -> 0.016667677 | H13: =+G13 -> 0.016667677 | I13: =+H13 -> 0.016667677 | J13: =+I13 -> 0.016667677 | K13: =+((((1+VLOOKUP(A13,'Inflación BE'!A:W,23))^12)/((1+VLOOKUP(A13,'Inflación BE'!A:O,15))^7))^(1/5))-1 -> 0.015333436 | L13: =+K13 -> 0.015333436 | M13: =+L13 -> 0.015333436 | N13: =+M13 -> 0.015333436 | O13: =+N13 -> 0.015333436 | P13: =+((1+C13)*(1+D13)*(1+E13)*(1+F13)*(1+G13)*(1+H13)*(1+I13)*(1+J13)*(1+K13)*(1+L13)*(1+M13)*(1+N13))-1 -> 0.24721606
... A18: =+'Inflación BE'!A47 -> 46043 | B18: =+VLOOKUP(A18,'Inflación BE'!A:G,7) -> 0.019866714 | C18: =+VLOOKUP(A18,'Inflación BE'!A:G,7) -> 0.019866714 | D18: =+VLOOKUP(A18,'Inflación BE'!A:S,19) -> 0.021099053 | E18: =+D18 -> 0.021099053 | F18: =+((((1+VLOOKUP(A18,'Inflación BE'!A:K,11))^3)/((1+E18)^2))^(1/1))-1 -> 0.019617828 | G18: =+((((1+VLOOKUP(A18,'Inflación BE'!A:O,15))^7)/((1+VLOOKUP(A18,'Inflación BE'!A:K,11))^3))^(1/4))-1 -> 0.015734208 | H18: =+G18 -> 0.015734208 | I18: =+H18 -> 0.015734208 | J18: =+I18 -> 0.015734208 | K18: =+((((1+VLOOKUP(A18,'Inflación BE'!A:W,23))^12)/((1+VLOOKUP(A18,'Inflación BE'!A:O,15))^7))^(1/5))-1 -> 0.01324709 | L18: =+K18 -> 0.01324709 | M18: =+L18 -> 0.01324709 | N18: =+M18 -> 0.01324709 | O18: =+N18 -> 0.01324709 | P18: =+((1+C18)*(1+D18)*(1+E18)*(1+F18)*(1+G18)*(1+H18)*(1+I18)*(1+J18)*(1+K18)*(1+L18)*(1+M18)*(1+N18))-1 -> 0.21646148
A19: =+'Inflación BE'!A48 -> 46044 | B19: 0.028452719 | C19: =+VLOOKUP(A19,'Inflación BE'!A:G,7) -> 0.019473233 | D19: =+VLOOKUP(A19,'Inflación BE'!A:S,19) -> 0.020241032 | E19: =+D19 -> 0.020241032 | F19: =+((((1+VLOOKUP(A19,'Inflación BE'!A:K,11))^3)/((1+E19)^2))^(1/1))-1 -> 0.021412175 | G19: =+((((1+VLOOKUP(A19,'Inflación BE'!A:O,15))^7)/((1+VLOOKUP(A19,'Inflación BE'!A:K,11))^3))^(1/4))-1 -> 0.016704103 | H19: =+G19 -> 0.016704103 | I19: =+H19 -> 0.016704103 | J19: =+I19 -> 0.016704103 | K19: =+((((1+VLOOKUP(A19,'Inflación BE'!A:W,23))^12)/((1+VLOOKUP(A19,'Inflación BE'!A:O,15))^7))^(1/5))-1 -> 0.013094025 | L19: =+K19 -> 0.013094025 | M19: =+L19 -> 0.013094025 | N19: =+M19 -> 0.013094025 | O19: =+N19 -> 0.013094025 | P19: =+((1+C19)*(1+D19)*(1+E19)*(1+F19)*(1+G19)*(1+H19)*(1+I19)*(1+J19)*(1+K19)*(1+L19)*(1+M19)*(1+N19))-1 -> 0.21999977
A20: =+'Inflación BE'!A49 -> 46045 | B20: 0.028452719 | C20: =+VLOOKUP(A20,'Inflación BE'!A:G,7) -> 0.023485758 | D20: =+VLOOKUP(A20,'Inflación BE'!A:S,19) -> 0.021254149 | E20: =+D20 -> 0.021254149 | F20: =+((((1+VLOOKUP(A20,'Inflación BE'!A:K,11))^3)/((1+E20)^2))^(1/1))-1 -> 0.021004562 | G20: =+((((1+VLOOKUP(A20,'Inflación BE'!A:O,15))^7)/((1+VLOOKUP(A20,'Inflación BE'!A:K,11))^3))^(1/4))-1 -> 0.016019358 | H20: =+G20 -> 0.016019358 | I20: =+H20 -> 0.016019358 | J20: =+I20 -> 0.016019358 | K20: =+((((1+VLOOKUP(A20,'Inflación BE'!A:W,23))^12)/((1+VLOOKUP(A20,'Inflación BE'!A:O,15))^7))^(1/5))-1 -> 0.013005756 | L20: =+K20 -> 0.013005756 | M20: =+L20 -> 0.013005756 | N20: =+M20 -> 0.013005756 | O20: =+N20 -> 0.013005756 | P20: =+((1+C20)*(1+D20)*(1+E20)*(1+F20)*(1+G20)*(1+H20)*(1+I20)*(1+J20)*(1+K20)*(1+L20)*(1+M20)*(1+N20))-1 -> 0.22301769
A21: =+'Inflación BE'!A50 -> 46048 | B21: 0.028452719 | C21: =+VLOOKUP(A21,'Inflación BE'!A:G,7) -> 0.022963372 | D21: =+VLOOKUP(A21,'Inflación BE'!A:S,19) -> 0.02135251 | E21: =+D21 -> 0.02135251 | F21: =+((((1+VLOOKUP(A21,'Inflación BE'!A:K,11))^3)/((1+E21)^2))^(1/1))-1 -> 0.021202007 | G21: =+((((1+VLOOKUP(A21,'Inflación BE'!A:O,15))^7)/((1+VLOOKUP(A21,'Inflación BE'!A:K,11))^3))^(1/4))-1 -> 0.015622956 | H21: =+G21 -> 0.015622956 | I21: =+H21 -> 0.015622956 | J21: =+I21 -> 0.015622956 | K21: =+((((1+VLOOKUP(A21,'Inflación BE'!A:W,23))^12)/((1+VLOOKUP(A21,'Inflación BE'!A:O,15))^7))^(1/5))-1 -> 0.013406808 | L21: =+K21 -> 0.013406808 | M21: =+L21 -> 0.013406808 | N21: =+M21 -> 0.013406808 | O21: =+N21 -> 0.013406808 | P21: =+((1+C21)*(1+D21)*(1+E21)*(1+F21)*(1+G21)*(1+H21)*(1+I21)*(1+J21)*(1+K21)*(1+L21)*(1+M21)*(1+N21))-1 -> 0.22289275
A22: =+'Inflación BE'!A51 -> 46049 | B22: 0.028452719 | C22: =+VLOOKUP(A22,'Inflación BE'!A:G,7) -> 0.023326798 | D22: =+VLOOKUP(A22,'Inflación BE'!A:S,19) -> 0.02028828 | E22: =+D22 -> 0.02028828 | F22: =+((((1+VLOOKUP(A22,'Inflación BE'!A:K,11))^3)/((1+E22)^2))^(1/1))-1 -> 0.022086286 | G22: =+((((1+VLOOKUP(A22,'Inflación BE'!A:O,15))^7)/((1+VLOOKUP(A22,'Inflación BE'!A:K,11))^3))^(1/4))-1 -> 0.016346972 | H22: =+G22 -> 0.016346972 | I22: =+H22 -> 0.016346972 | J22: =+I22 -> 0.016346972 | K22: =+((((1+VLOOKUP(A22,'Inflación BE'!A:W,23))^12)/((1+VLOOKUP(A22,'Inflación BE'!A:O,15))^7))^(1/5))-1 -> 0.012370238 | L22: =+K22 -> 0.012370238 | M22: =+L22 -> 0.012370238 | N22: =+M22 -> 0.012370238 | O22: =+N22 -> 0.012370238 | P22: =+((1+C22)*(1+D22)*(1+E22)*(1+F22)*(1+G22)*(1+H22)*(1+I22)*(1+J22)*(1+K22)*(1+L22)*(1+M22)*(1+N22))-1 -> 0.22031844
A23: =+'Inflación BE'!A52 -> 46050 | B23: 0.028452719 | C23: =+VLOOKUP(A23,'Inflación BE'!A:G,7) -> 0.023575723 | D23: =+VLOOKUP(A23,'Inflación BE'!A:S,19) -> 0.018965761 | E23: =+D23 -> 0.018965761 | F23: =+((((1+VLOOKUP(A23,'Inflación BE'!A:K,11))^3)/((1+E23)^2))^(1/1))-1 -> 0.025044526 | G23: =+((((1+VLOOKUP(A23,'Inflación BE'!A:O,15))^7)/((1+VLOOKUP(A23,'Inflación BE'!A:K,11))^3))^(1/4))-1 -> 0.01533744 | H23: =+G23 -> 0.01533744 | I23: =+H23 -> 0.01533744 | J23: =+I23 -> 0.01533744 | K23: =+((((1+VLOOKUP(A23,'Inflación BE'!A:W,23))^12)/((1+VLOOKUP(A23,'Inflación BE'!A:O,15))^7))^(1/5))-1 -> 0.012988364 | L23: =+K23 -> 0.012988364 | M23: =+L23 -> 0.012988364 | N23: =+M23 -> 0.012988364 | O23: =+N23 -> 0.012988364 | P23: =+((1+C23)*(1+D23)*(1+E23)*(1+F23)*(1+G23)*(1+H23)*(1+I23)*(1+J23)*(1+K23)*(1+L23)*(1+M23)*(1+N23))-1 -> 0.21910559
A24: =+'Inflación BE'!A53 -> 46051 | B24: 0.028452719 | C24: =+VLOOKUP(A24,'Inflación BE'!A:G,7) -> 0.023465328 | D24: =+VLOOKUP(A24,'Inflación BE'!A:S,19) -> 0.020390806 | E24: =+D24 -> 0.020390806 | F24: =+((((1+VLOOKUP(A24,'Inflación BE'!A:K,11))^3)/((1+E24)^2))^(1/1))-1 -> 0.019315437 | G24: =+((((1+VLOOKUP(A24,'Inflación BE'!A:O,15))^7)/((1+VLOOKUP(A24,'Inflación BE'!A:K,11))^3))^(1/4))-1 -> 0.015817118 | H24: =+G24 -> 0.015817118 | I24: =+H24 -> 0.015817118 | J24: =+I24 -> 0.015817118 | K24: =+((((1+VLOOKUP(A24,'Inflación BE'!A:W,23))^12)/((1+VLOOKUP(A24,'Inflación BE'!A:O,15))^7))^(1/5))-1 -> 0.013231861 | L24: =+K24 -> 0.013231861 | M24: =+L24 -> 0.013231861 | N24: =+M24 -> 0.013231861 | O24: =+N24 -> 0.013231861 | P24: =+((1+C24)*(1+D24)*(1+E24)*(1+F24)*(1+G24)*(1+H24)*(1+I24)*(1+J24)*(1+K24)*(1+L24)*(1+M24)*(1+N24))-1 -> 0.21902403
A25: =+'Inflación BE'!A54 -> 46052 | B25: 0.028452719 | C25: =+VLOOKUP(A25,'Inflación BE'!A:G,7) -> 0.026316358 | D25: =+VLOOKUP(A25,'Inflación BE'!A:S,19) -> 0.020639232 | E25: =+D25 -> 0.020639232 | F25: =+((((1+VLOOKUP(A25,'Inflación BE'!A:K,11))^3)/((1+E25)^2))^(1/1))-1 -> 0.019297539 | G25: =+((((1+VLOOKUP(A25,'Inflación BE'!A:O,15))^7)/((1+VLOOKUP(A25,'Inflación BE'!A:K,11))^3))^(1/4))-1 -> 0.015444846 | H25: =+G25 -> 0.015444846 | I25: =+H25 -> 0.015444846 | J25: =+I25 -> 0.015444846 | K25: =+((((1+VLOOKUP(A25,'Inflación BE'!A:W,23))^12)/((1+VLOOKUP(A25,'Inflación BE'!A:O,15))^7))^(1/5))-1 -> 0.013534091 | L25: =+K25 -> 0.013534091 | M25: =+L25 -> 0.013534091 | N25: =+M25 -> 0.013534091 | O25: =+N25 -> 0.013534091 | P25: =+((1+C25)*(1+D25)*(1+E25)*(1+F25)*(1+G25)*(1+H25)*(1+I25)*(1+J25)*(1+K25)*(1+L25)*(1+M25)*(1+N25))-1 -> 0.22265955
A26: =+'Inflación BE'!A55 -> 46055 | B26: 0.028452719 | C26: =+VLOOKUP(A26,'Inflación BE'!A:G,7) -> 0.025344712 | D26: =+VLOOKUP(A26,'Inflación BE'!A:S,19) -> 0.019841239 | E26: =+D26 -> 0.019841239 | F26: =+((((1+VLOOKUP(A26,'Inflación BE'!A:K,11))^3)/((1+E26)^2))^(1/1))-1 -> 0.020553006 | G26: =+((((1+VLOOKUP(A26,'Inflación BE'!A:O,15))^7)/((1+VLOOKUP(A26,'Inflación BE'!A:K,11))^3))^(1/4))-1 -> 0.014981326 | H26: =+G26 -> 0.014981326 | I26: =+H26 -> 0.014981326 | J26: =+I26 -> 0.014981326 | K26: =+((((1+VLOOKUP(A26,'Inflación BE'!A:W,23))^12)/((1+VLOOKUP(A26,'Inflación BE'!A:O,15))^7))^(1/5))-1 -> 0.013956989 | L26: =+K26 -> 0.013956989 | M26: =+L26 -> 0.013956989 | N26: =+M26 -> 0.013956989 | O26: =+N26 -> 0.013956989 | P26: =+((1+C26)*(1+D26)*(1+E26)*(1+F26)*(1+G26)*(1+H26)*(1+I26)*(1+J26)*(1+K26)*(1+L26)*(1+M26)*(1+N26))-1 -> 0.22090238
A27: =+'Inflación BE'!A56 -> 46056 | B27: 0.028452719 | C27: =+VLOOKUP(A27,'Inflación BE'!A:G,7) -> 0.024969362 | D27: =+VLOOKUP(A27,'Inflación BE'!A:S,19) -> 0.021806769 | E27: =+D27 -> 0.021806769 | F27: =+((((1+VLOOKUP(A27,'Inflación BE'!A:K,11))^3)/((1+E27)^2))^(1/1))-1 -> 0.018291567 | G27: =+((((1+VLOOKUP(A27,'Inflación BE'!A:O,15))^7)/((1+VLOOKUP(A27,'Inflación BE'!A:K,11))^3))^(1/4))-1 -> 0.015917933 | H27: =+G27 -> 0.015917933 | I27: =+H27 -> 0.015917933 | J27: =+I27 -> 0.015917933 | K27: =+((((1+VLOOKUP(A27,'Inflación BE'!A:W,23))^12)/((1+VLOOKUP(A27,'Inflación BE'!A:O,15))^7))^(1/5))-1 -> 0.01302176 | L27: =+K27 -> 0.01302176 | M27: =+L27 -> 0.01302176 | N27: =+M27 -> 0.01302176 | O27: =+N27 -> 0.01302176 | P27: =+((1+C27)*(1+D27)*(1+E27)*(1+F27)*(1+G27)*(1+H27)*(1+I27)*(1+J27)*(1+K27)*(1+L27)*(1+M27)*(1+N27))-1 -> 0.22244741
A28: =+'Inflación BE'!A57 -> 46057 | B28: 0.028452719 | C28: =+VLOOKUP(A28,'Inflación BE'!A:G,7) -> 0.02543152 | D28: =+VLOOKUP(A28,'Inflación BE'!A:S,19) -> 0.021265287 | E28: =+D28 -> 0.021265287 | F28: =+((((1+VLOOKUP(A28,'Inflación BE'!A:K,11))^3)/((1+E28)^2))^(1/1))-1 -> 0.020741221 | G28: =+((((1+VLOOKUP(A28,'Inflación BE'!A:O,15))^7)/((1+VLOOKUP(A28,'Inflación BE'!A:K,11))^3))^(1/4))-1 -> 0.01667381 | H28: =+G28 -> 0.01667381 | I28: =+H28 -> 0.01667381 | J28: =+I28 -> 0.01667381 | K28: =+((((1+VLOOKUP(A28,'Inflación BE'!A:W,23))^12)/((1+VLOOKUP(A28,'Inflación BE'!A:O,15))^7))^(1/5))-1 -> 0.012985997 | L28: =+K28 -> 0.012985997 | M28: =+L28 -> 0.012985997 | N28: =+M28 -> 0.012985997 | O28: =+N28 -> 0.012985997 | P28: =+((1+C28)*(1+D28)*(1+E28)*(1+F28)*(1+G28)*(1+H28)*(1+I28)*(1+J28)*(1+K28)*(1+L28)*(1+M28)*(1+N28))-1 -> 0.22811707
A29: =+'Inflación BE'!A58 -> 46058 | B29: 0.028452719 | C29: =+VLOOKUP(A29,'Inflación BE'!A:G,7) -> 0.025848458 | D29: =+VLOOKUP(A29,'Inflación BE'!A:S,19) -> 0.022859723 | E29: =+D29 -> 0.022859723 | F29: =+((((1+VLOOKUP(A29,'Inflación BE'!A:K,11))^3)/((1+E29)^2))^(1/1))-1 -> 0.022705364 | G29: =+((((1+VLOOKUP(A29,'Inflación BE'!A:O,15))^7)/((1+VLOOKUP(A29,'Inflación BE'!A:K,11))^3))^(1/4))-1 -> 0.01648298 | H29: =+G29 -> 0.01648298 | I29: =+H29 -> 0.01648298 | J29: =+I29 -> 0.01648298 | K29: =+((((1+VLOOKUP(A29,'Inflación BE'!A:W,23))^12)/((1+VLOOKUP(A29,'Inflación BE'!A:O,15))^7))^(1/5))-1 -> 0.013774033 | L29: =+K29 -> 0.013774033 | M29: =+L29 -> 0.013774033 | N29: =+M29 -> 0.013774033 | O29: =+N29 -> 0.013774033 | P29: =+((1+C29)*(1+D29)*(1+E29)*(1+F29)*(1+G29)*(1+H29)*(1+I29)*(1+J29)*(1+K29)*(1+L29)*(1+M29)*(1+N29))-1 -> 0.23774447
A30: =+'Inflación BE'!A59 -> 46059 | B30: 0.028452719 | C30: =+VLOOKUP(A30,'Inflación BE'!A:G,7) -> 0.02734239 | D30: =+VLOOKUP(A30,'Inflación BE'!A:S,19) -> 0.023602861 | E30: =+D30 -> 0.023602861 | F30: =+((((1+VLOOKUP(A30,'Inflación BE'!A:K,11))^3)/((1+E30)^2))^(1/1))-1 -> 0.022576267 | G30: =+((((1+VLOOKUP(A30,'Inflación BE'!A:O,15))^7)/((1+VLOOKUP(A30,'Inflación BE'!A:K,11))^3))^(1/4))-1 -> 0.017362683 | H30: =+G30 -> 0.017362683 | I30: =+H30 -> 0.017362683 | J30: =+I30 -> 0.017362683 | K30: =+((((1+VLOOKUP(A30,'Inflación BE'!A:W,23))^12)/((1+VLOOKUP(A30,'Inflación BE'!A:O,15))^7))^(1/5))-1 -> 0.012949121 | L30: =+K30 -> 0.012949121 | M30: =+L30 -> 0.012949121 | N30: =+M30 -> 0.012949121 | O30: =+N30 -> 0.012949121 | P30: =+((1+C30)*(1+D30)*(1+E30)*(1+F30)*(1+G30)*(1+H30)*(1+I30)*(1+J30)*(1+K30)*(1+L30)*(1+M30)*(1+N30))-1 -> 0.24144545
... A32: =+'Inflación BE'!A61 -> 46063 | B32: 0.028452719 | C32: =+VLOOKUP(A32,'Inflación BE'!A:G,7) -> 0.030218127 | D32: =+VLOOKUP(A32,'Inflación BE'!A:S,19) -> 0.024180328 | E32: =+D32 -> 0.024180328 | F32: =+((((1+VLOOKUP(A32,'Inflación BE'!A:K,11))^3)/((1+E32)^2))^(1/1))-1 -> 0.023070151 | G32: =+((((1+VLOOKUP(A32,'Inflación BE'!A:O,15))^7)/((1+VLOOKUP(A32,'Inflación BE'!A:K,11))^3))^(1/4))-1 -> 0.018102814 | H32: =+G32 -> 0.018102814 | I32: =+H32 -> 0.018102814 | J32: =+I32 -> 0.018102814 | K32: =+((((1+VLOOKUP(A32,'Inflación BE'!A:W,23))^12)/((1+VLOOKUP(A32,'Inflación BE'!A:O,15))^7))^(1/5))-1 -> 0.012064886 | L32: =+K32 -> 0.012064886 | M32: =+L32 -> 0.012064886 | N32: =+M32 -> 0.012064886 | O32: =+N32 -> 0.012064886 | P32: =+((1+C32)*(1+D32)*(1+E32)*(1+F32)*(1+G32)*(1+H32)*(1+I32)*(1+J32)*(1+K32)*(1+L32)*(1+M32)*(1+N32))-1 -> 0.24619912
A33: =+'Inflación BE'!A62 -> 46064 | B33: 0.028452719 | C33: 0.028816194 | D33: =+VLOOKUP(A33,'Inflación BE'!A:S,19) -> 0.024063761 | E33: =+D33 -> 0.024063761 | F33: =+((((1+VLOOKUP(A33,'Inflación BE'!A:K,11))^3)/((1+E33)^2))^(1/1))-1 -> 0.02402409 | G33: =+((((1+VLOOKUP(A33,'Inflación BE'!A:O,15))^7)/((1+VLOOKUP(A33,'Inflación BE'!A:K,11))^3))^(1/4))-1 -> 0.016515431 | H33: =+G33 -> 0.016515431 | I33: =+H33 -> 0.016515431 | J33: =+I33 -> 0.016515431 | K33: =+((((1+VLOOKUP(A33,'Inflación BE'!A:W,23))^12)/((1+VLOOKUP(A33,'Inflación BE'!A:O,15))^7))^(1/5))-1 -> 0.013244783 | L33: =+K33 -> 0.013244783 | M33: =+L33 -> 0.013244783 | N33: =+M33 -> 0.013244783 | O33: =+N33 -> 0.013244783 | P33: =+((1+C33)*(1+D33)*(1+E33)*(1+F33)*(1+G33)*(1+H33)*(1+I33)*(1+J33)*(1+K33)*(1+L33)*(1+M33)*(1+N33))-1 -> 0.2434129
